Workbook

Sheet Inicio
B2: GRIFF SALUD SA
B3: Tablero de Facturación e Impuestos
B4: Período: 2026
B6: Datos de la empresa
B7: Razón Social: | C7: GRIFF SALUD SA
B8: CUIT: | C8: 30-71713418-0
B9: Forma Jurídica: | C9: Sociedad Anónima
B10: Domicilio Fiscal: | C10: Loreto Virrey 1710, Piso 10 Dpto E - CABA
B11: Condición AFIP: | C11: Responsable Inscripto
B12: Inicio actividades: | C12: 10/2025
B13: Cierre ejercicio: | C13: Diciembre
B14: Actividad principal: | C14: 869090 - Servicios relacionados con la salud humana NCP
B15: Actividad secundaria: | C15: 702010 - Servicios de gerenciamiento de instituciones de salud
B16: Actividades IIBB: | C16: 702010 - Gerenciamiento / 651110 - Servicios de seguros
B17: Jurisdicciones IIBB: | C17: Convenio Multilateral - CABA (901) + Córdoba (904)
B18: Tasa Municipal: | C18: Comercio e Industria - Córdoba
B20: Estructura del libro
B21: Reglas | C21: Alícuotas, coeficientes y parámetros editables. ⚠️ Modificar acá los valores fiscales.
B22: Facturacion | C22: Registro maestro: una fila por factura emitida. Base de todos los cálculos.
B23: Checklist | C23: Control mensual de facturas a emitir por cliente fijo. Verde = emitida, Rojo = falta.
B24: Cobranzas | C24: Estado de cobro de cada factura. Por ahora manual.
B25: Impuestos | C25: Cálculo automático mensual: IVA, IIBB CABA, IIBB Córdoba, Tasa Comercio.
B26: Resumen | C26: Vista ejecutiva: totales del año, próximos vencimientos, alertas.
B28: Convenciones de color
B29: Texto azul | C29: Datos cargados manualmente (editables)
B30: Texto negro | C30: Fórmulas calculadas automáticamente (no editar)
B31: Texto verde | C31: Referencia a otra hoja del libro
B32: Fondo amarillo | C32: Parámetro clave - revisar y ajustar
B34: ℹ️ Importante
B35: Todos los cálculos de impuestos son APROXIMADOS. No reemplazan la liquidación profesional. El crédito fiscal de IVA es estimado por prorrateo (parametrizable en hoja Reglas). Las retenciones, percepciones y pagos a cuenta deben cargarse en hoja Impuestos al recibir los certificados. NOTAS DE CRÉDITO: cargar Tipo como 'NCA', 'NCB', 'NCC' o 'NCE'. Los montos se ingresan en POSITIVO; el sistema invierte el signo automáticamente y resta del IVA, IIBB y demás impuestos del período.

Sheet Reglas
B2: REGLAS Y PARÁMETROS FISCALES
B3: Modifique los valores en azul / fondo amarillo. Las fórmulas del resto del libro los toman automáticamente.
B5: 1. IVA
B6: Concepto | C6: Valor | F6: Notas
B7: Alícuota IVA general | C7: 0.21 | F7: 21% - alícuota general para servicios
B8: Alícuota IVA reducida | C8: 0.105 | F8: 10,5% - servicios de salud, intereses, etc.
B9: Crédito fiscal - método | C9: Prorrateo | F9: Prorrateo aproximado: IVA crédito = % débito mensual
B10: % Crédito fiscal estimado (sobre débito) | C10: 0.3 | F10: ⚠️ AJUSTAR según realidad: % de IVA crédito como proporción del débito
B12: 2. IIBB - Convenio Multilateral
B13: Jurisdicción | C13: Código | D13: Coef. Unificado | F13: Notas
B14: CABA | C14: 901 | D14: 0.0433 | F14: Coeficiente unificado Convenio Multilateral 2026
B15: Córdoba | C15: 904 | D15: 0.9567 | F15: Coeficiente unificado Convenio Multilateral 2026
B16: Suma coeficientes (debe ser 1,0000) | D16: =Reglas!$D$14+Reglas!$D$15
B18: 3. IIBB - Alícuotas por actividad y jurisdicción
B19: Código actividad | C19: Descripción | D19: Alícuota CABA | E19: Alícuota Córdoba | F19: Notas
B20: 702010 | C20: Servicios de gerenciamiento de instituciones de salud | D20: 0.03 | E20: 0.055 | F20: Honorarios, administración, gerenciamiento
B21: 651110 | C21: Servicios de seguros de salud | D21: 0.055 | E21: 0.03 | F21: Capitas, refuerzos de cápita, vacunación, enfermería
B23: 4. Tasa Comercio e Industria - Municipalidad de Córdoba
B24: Año | C24: Alícuota | F24: Notas
B25: 2025 | C25: 0.05 | F25: Alícuota vigente 2025
B26: 2026 | C26: 0.049 | F26: Alícuota vigente 2026
B27: Aplica solo a actividad en Córdoba (Cba en CM)
B29: 5. Mapeo de Concepto → Actividad IIBB
B30: Texto en el concepto (en mayúsculas o minúsculas) | C30: Actividad | D30: Notas
B31: CAPITA | C31: 651110 | D31: Capitas - servicio de seguro
B32: REFUERZO | C32: 651110 | D32: Refuerzo de cápita
B33: VACUNACION | C33: 651110 | D33: Convenio de vacunación
B34: ENFERMERIA | C34: 651110 | D34: Convenio de enfermería
B35: APORTES | C35: 651110 | D35: Aportes MMRC u otros
B36: HONORARIOS | C36: 702010 | D36: Honorarios prestacionales/administrativos
B37: ADMINISTRACION | C37: 702010 | D37: Honorarios de administración
B38: GERENCIAMIENTO | C38: 702010 | D38: Servicios de gerenciamiento
B39: ALQUILER | C39: 702010 | D39: Alquiler ecógrafo / equipos
B40: AUDITORIA | C40: 702010 | D40: Servicios de auditoría
B41: PRESTACIONAL | C41: 702010 | D41: Servicios prestacionales generales
B42: OTROS | C42: 702010 | D42: Cualquier otro concepto - default
B44: 6. Distribución de facturación por actividad (auto - lectura desde hoja Facturación)
B45: Cada factura se asigna a una actividad según el mapeo del punto 5. La distribución por jurisdicción se hace con los coeficientes del punto 2.
B47: 7. Vencimientos (informativo)
B48: Impuesto | C48: Día vencimiento | F48: Notas
...

Sheet Facturacion
A1: Fecha | B1: Tipo | C1: Pto Vta | D1: Número | E1: Cliente | F1: CUIT | G1: Concepto | H1: Actividad IIBB | I1: Neto Gravado | J1: No Grav. / Exento | K1: IVA 21% | L1: IVA 10,5% | M1: Percepciones | N1: Total | O1: Período | P1: Año | Q1: Mes | R1: Estado AFIP | S1: Estado Cobro | T1: Fecha Cobro | U1: Monto Cobrado | V1: Saldo Pendiente | W1: Observaciones | X1: Signo | Y1: Neto Efectivo | Z1: NoGrav Efectivo | AA1: IVA21 Efectivo | AB1: IVA105 Efectivo | AC1: Total Efectivo
A2: 46143 | B2: NCB | C2: 1 | D2: 55 | E2: OSSURRBAC | F2: 30714341746 | G2: Error Monto - Servicios prestacionales | H2: =IF(G2="","",IF(ISNUMBER(SEARCH("CAPITA",UPPER(G2))),651110,IF(ISNUMBER(SEARCH("REFUERZO",UPPER(G2))),651110,IF(ISNUMBER(SEARCH("VACUNACION",UPPER(G2))),651110,IF(ISNUMBER(SEARCH("ENFERMERIA",UPPER(G2))),651110,IF(ISNUMBER(SEARCH("APORTES",UPPER(G2))),651110,IF(ISNUMBER(SEARCH("HONORARIOS",UPPER(G2))),702010,IF(ISNUMBER(SEARCH("ADMINISTRACION",UPPER(G2))),702010,IF(ISNUMBER(SEARCH("GERENCIAMIENTO",UPPER(G2))),702010,IF(ISNUMBER(SEARCH("ALQUILER",UPPER(G2))),702010,IF(ISNUMBER(SEARCH("AUDITORIA",UPPER(G2))),702010,IF(ISNUMBER(SEARCH("PRESTACIONAL",UPPER(G2))),702010,702010)))))))))))) | I2: 0 | J2: 1320000 | K2: =IF(N(I2)>0,ROUND(N(I2)*IVA_general,2),0) | L2: 0 | M2: 0 | N2: =IF(SUM(I2:M2)=0,"",SUM(I2:M2)) | O2: =IF(A2="","",TEXT(A2,"yyyy-mm")) | P2: =IF(A2="","",YEAR(A2)) | Q2: =IF(A2="","",MONTH(A2)) | R2: Emitida | S2: Pendiente | U2: 0 | V2: =IF(B2="","",N2-U2) | W2: Auto: 30717134180_008_00001_00000055 (1).pdf | OBRA SOCIAL DEL SINDICATO UNICO DE RECOLECTORES DE RESIDUOS | X2: =IF(B2="","",IF(LEFT(B2,2)="NC",-1,1)) | Y2: =IF(B2="",0,N(I2)*X2) | Z2: =IF(B2="",0,N(J2)*X2) | AA2: =IF(B2="",0,N(K2)*X2) | AB2: =IF(B2="",0,N(L2)*X2) | AC2: =IF(B2="",0,N(N2)*X2)
A3: 46143 | B3: B | C3: 1 | D3: 612 | E3: AMSURRBAC | F3: 30710660995 | G3: Capita correspondiente al mes de | H3: =IF(G3="","",IF(ISNUMBER(SEARCH("CAPITA",UPPER(G3))),651110,IF(ISNUMBER(SEARCH("REFUERZO",UPPER(G3))),651110,IF(ISNUMBER(SEARCH("VACUNACION",UPPER(G3))),651110,IF(ISNUMBER(SEARCH("ENFERMERIA",UPPER(G3))),651110,IF(ISNUMBER(SEARCH("APORTES",UPPER(G3))),651110,IF(ISNUMBER(SEARCH("HONORARIOS",UPPER(G3))),702010,IF(ISNUMBER(SEARCH("ADMINISTRACION",UPPER(G3))),702010,IF(ISNUMBER(SEARCH("GERENCIAMIENTO",UPPER(G3))),702010,IF(ISNUMBER(SEARCH("ALQUILER",UPPER(G3))),702010,IF(ISNUMBER(SEARCH("AUDITORIA",UPPER(G3))),702010,IF(ISNUMBER(SEARCH("PRESTACIONAL",UPPER(G3))),702010,702010)))))))))))) | I3: 0 | J3: 2827915.2 | K3: =IF(N(I3)>0,ROUND(N(I3)*IVA_general,2),0) | L3: 0 | M3: 0 | N3: =IF(SUM(I3:M3)=0,"",SUM(I3:M3)) | O3: =IF(A3="","",TEXT(A3,"yyyy-mm")) | P3: =IF(A3="","",YEAR(A3)) | Q3: =IF(A3="","",MONTH(A3)) | R3: Emitida | S3: Pendiente | U3: 0 | V3: =IF(B3="","",N3-U3) | W3: Auto: 30717134180_006_00001_00000612 (1).pdf | MUTUAL ASOCIACION MUTUAL DEL SINDICATO UNICO DE RECOLECTORES | X3: =IF(B3="","",IF(LEFT(B3,2)="NC",-1,1)) | Y3: =IF(B3="",0,N(I3)*X3) | Z3: =IF(B3="",0,N(J3)*X3) | AA3: =IF(B3="",0,N(K3)*X3) | AB3: =IF(B3="",0,N(L3)*X3) | AC3: =IF(B3="",0,N(N3)*X3)
A4: 46143 | B4: B | C4: 1 | D4: 613 | E4: AMSURRBAC | F4: 30710660995 | G4: Capita correspondiente al mes de | H4: =IF(G4="","",IF(ISNUMBER(SEARCH("CAPITA",UPPER(G4))),651110,IF(ISNUMBER(SEARCH("REFUERZO",UPPER(G4))),651110,IF(ISNUMBER(SEARCH("VACUNACION",UPPER(G4))),651110,IF(ISNUMBER(SEARCH("ENFERMERIA",UPPER(G4))),651110,IF(ISNUMBER(SEARCH("APORTES",UPPER(G4))),651110,IF(ISNUMBER(SEARCH("HONORARIOS",UPPER(G4))),702010,IF(ISNUMBER(SEARCH("ADMINISTRACION",UPPER(G4))),702010,IF(ISNUMBER(SEARCH("GERENCIAMIENTO",UPPER(G4))),702010,IF(ISNUMBER(SEARCH("ALQUILER",UPPER(G4))),702010,IF(ISNUMBER(SEARCH("AUDITORIA",UPPER(G4))),702010,IF(ISNUMBER(SEARCH("PRESTACIONAL",UPPER(G4))),702010,702010)))))))))))) | I4: 0 | J4: 2965651.9 | K4: =IF(N(I4)>0,ROUND(N(I4)*IVA_general,2),0) | L4: 0 | M4: 0 | N4: =IF(SUM(I4:M4)=0,"",SUM(I4:M4)) | O4: =IF(A4="","",TEXT(A4,"yyyy-mm")) | P4: =IF(A4="","",YEAR(A4)) | Q4: =IF(A4="","",MONTH(A4)) | R4: Emitida | S4: Pendiente | U4: 0 | V4: =IF(B4="","",N4-U4) | W4: Auto: 30717134180_006_00001_00000613 (1).pdf | MUTUAL ASOCIACION MUTUAL DEL SINDICATO UNICO DE RECOLECTORES | X4: =IF(B4="","",IF(LEFT(B4,2)="NC",-1,1)) | Y4: =IF(B4="",0,N(I4)*X4) | Z4: =IF(B4="",0,N(J4)*X4) | AA4: =IF(B4="",0,N(K4)*X4) | AB4: =IF(B4="",0,N(L4)*X4) | AC4: =IF(B4="",0,N(N4)*X4)
A5: 46143 | B5: B | C5: 1 | D5: 614 | E5: OSPEVIC | F5: 30606579906 | G5: Capitas mensuales periodo Abril 2026 | H5: =IF(G5="","",IF(ISNUMBER(SEARCH("CAPITA",UPPER(G5))),651110,IF(ISNUMBER(SEARCH("REFUERZO",UPPER(G5))),651110,IF(ISNUMBER(SEARCH("VACUNACION",UPPER(G5))),651110,IF(ISNUMBER(SEARCH("ENFERMERIA",UPPER(G5))),651110,IF(ISNUMBER(SEARCH("APORTES",UPPER(G5))),651110,IF(ISNUMBER(SEARCH("HONORARIOS",UPPER(G5))),702010,IF(ISNUMBER(SEARCH("ADMINISTRACION",UPPER(G5))),702010,IF(ISNUMBER(SEARCH("GERENCIAMIENTO",UPPER(G5))),702010,IF(ISNUMBER(SEARCH("ALQUILER",UPPER(G5))),702010,IF(ISNUMBER(SEARCH("AUDITORIA",UPPER(G5))),702010,IF(ISNUMBER(SEARCH("PRESTACIONAL",UPPER(G5))),702010,702010)))))))))))) | I5: 0 | J5: 1.9867229e+08 | K5: =IF(N(I5)>0,ROUND(N(I5)*IVA_general,2),0) | L5: 0 | M5: 0 | N5: =IF(SUM(I5:M5)=0,"",SUM(I5:M5)) | O5: =IF(A5="","",TEXT(A5,"yyyy-mm")) | P5: =IF(A5="","",YEAR(A5)) | Q5: =IF(A5="","",MONTH(A5)) | R5: Emitida | S5: Cobrada | U5: 1.9867229e+08 | V5: =IF(B5="","",N5-U5) | W5: Auto: 30717134180_006_00001_00000614 (1).pdf | OBRA SOCIAL DEL PERSONAL DE VIGILANCIA Y SEGURIDAD COMERCIAL | X5: =IF(B5="","",IF(LEFT(B5,2)="NC",-1,1)) | Y5: =IF(B5="",0,N(I5)*X5) | Z5: =IF(B5="",0,N(J5)*X5) | AA5: =IF(B5="",0,N(K5)*X5) | AB5: =IF(B5="",0,N(L5)*X5) | AC5: =IF(B5="",0,N(N5)*X5)
A6: 46143 | B6: B | C6: 1 | D6: 615 | E6: OSSURRBAC | F6: 30714341746 | G6: Servicios prestacionales ecografo Abril | H6: =IF(G6="","",IF(ISNUMBER(SEARCH("CAPITA",UPPER(G6))),651110,IF(ISNUMBER(SEARCH("REFUERZO",UPPER(G6))),651110,IF(ISNUMBER(SEARCH("VACUNACION",UPPER(G6))),651110,IF(ISNUMBER(SEARCH("ENFERMERIA",UPPER(G6))),651110,IF(ISNUMBER(SEARCH("APORTES",UPPER(G6))),651110,IF(ISNUMBER(SEARCH("HONORARIOS",UPPER(G6))),702010,IF(ISNUMBER(SEARCH("ADMINISTRACION",UPPER(G6))),702010,IF(ISNUMBER(SEARCH("GERENCIAMIENTO",UPPER(G6))),702010,IF(ISNUMBER(SEARCH("ALQUILER",UPPER(G6))),702010,IF(ISNUMBER(SEARCH("AUDITORIA",UPPER(G6))),702010,IF(ISNUMBER(SEARCH("PRESTACIONAL",UPPER(G6))),702010,702010)))))))))))) | I6: 3713132.9 | J6: 0 | K6: =IF(N(I6)>0,ROUND(N(I6)*IVA_general,2),0) | L6: 0 | M6: 0 | N6: =IF(SUM(I6:M6)=0,"",SUM(I6:M6)) | O6: =IF(A6="","",TEXT(A6,"yyyy-mm")) | P6: =IF(A6="","",YEAR(A6)) | Q6: =IF(A6="","",MONTH(A6)) | R6: Emitida | S6: Pendiente | U6: 0 | V6: =IF(B6="","",N6-U6) | W6: Auto: 30717134180_006_00001_00000615 (1).pdf | OBRA SOCIAL DEL SINDICATO UNICO DE RECOLECTORES DE RESIDUOS | X6: =IF(B6="","",IF(LEFT(B6,2)="NC",-1,1)) | Y6: =IF(B6="",0,N(I6)*X6) | Z6: =IF(B6="",0,N(J6)*X6) | AA6: =IF(B6="",0,N(K6)*X6) | AB6: =IF(B6="",0,N(L6)*X6) | AC6: =IF(B6="",0,N(N6)*X6)
A7: 46143 | B7: B | C7: 1 | D7: 616 | E7: OSSURRBAC | F7: 30714341746 | G7: Capita correspondiente al mes de Abril | H7: =IF(G7="","",IF(ISNUMBER(SEARCH("CAPITA",UPPER(G7))),651110,IF(ISNUMBER(SEARCH("REFUERZO",UPPER(G7))),651110,IF(ISNUMBER(SEARCH("VACUNACION",UPPER(G7))),651110,IF(ISNUMBER(SEARCH("ENFERMERIA",UPPER(G7))),651110,IF(ISNUMBER(SEARCH("APORTES",UPPER(G7))),651110,IF(ISNUMBER(SEARCH("HONORARIOS",UPPER(G7))),702010,IF(ISNUMBER(SEARCH("ADMINISTRACION",UPPER(G7))),702010,IF(ISNUMBER(SEARCH("GERENCIAMIENTO",UPPER(G7))),702010,IF(ISNUMBER(SEARCH("ALQUILER",UPPER(G7))),702010,IF(ISNUMBER(SEARCH("AUDITORIA",UPPER(G7))),702010,IF(ISNUMBER(SEARCH("PRESTACIONAL",UPPER(G7))),702010,702010)))))))))))) | I7: 0 | J7: 7893768.1 | K7: =IF(N(I7)>0,ROUND(N(I7)*IVA_general,2),0) | L7: 0 | M7: 0 | N7: =IF(SUM(I7:M7)=0,"",SUM(I7:M7)) | O7: =IF(A7="","",TEXT(A7,"yyyy-mm")) | P7: =IF(A7="","",YEAR(A7)) | Q7: =IF(A7="","",MONTH(A7)) | R7: Emitida | S7: Pendiente | U7: 0 | V7: =IF(B7="","",N7-U7) | W7: Auto: 30717134180_006_00001_00000616 (1).pdf | OBRA SOCIAL DEL SINDICATO UNICO DE RECOLECTORES DE RESIDUOS | X7: =IF(B7="","",IF(LEFT(B7,2)="NC",-1,1)) | Y7: =IF(B7="",0,N(I7)*X7) | Z7: =IF(B7="",0,N(J7)*X7) | AA7: =IF(B7="",0,N(K7)*X7) | AB7: =IF(B7="",0,N(L7)*X7) | AC7: =IF(B7="",0,N(N7)*X7)
A8: 46143 | B8: B | C8: 1 | D8: 617 | E8: OSPLYF | F8: 30565846538 | G8: Capita correspondiente al mes de Abril | H8: =IF(G8="","",IF(ISNUMBER(SEARCH("CAPITA",UPPER(G8))),651110,IF(ISNUMBER(SEARCH("REFUERZO",UPPER(G8))),651110,IF(ISNUMBER(SEARCH("VACUNACION",UPPER(G8))),651110,IF(ISNUMBER(SEARCH("ENFERMERIA",UPPER(G8))),651110,IF(ISNUMBER(SEARCH("APORTES",UPPER(G8))),651110,IF(ISNUMBER(SEARCH("HONORARIOS",UPPER(G8))),702010,IF(ISNUMBER(SEARCH("ADMINISTRACION",UPPER(G8))),702010,IF(ISNUMBER(SEARCH("GERENCIAMIENTO",UPPER(G8))),702010,IF(ISNUMBER(SEARCH("ALQUILER",UPPER(G8))),702010,IF(ISNUMBER(SEARCH("AUDITORIA",UPPER(G8))),702010,IF(ISNUMBER(SEARCH("PRESTACIONAL",UPPER(G8))),702010,702010)))))))))))) | I8: 0 | J8: 18001763 | K8: =IF(N(I8)>0,ROUND(N(I8)*IVA_general,2),0) | L8: 0 | M8: 0 | N8: =IF(SUM(I8:M8)=0,"",SUM(I8:M8)) | O8: =IF(A8="","",TEXT(A8,"yyyy-mm")) | P8: =IF(A8="","",YEAR(A8)) | Q8: =IF(A8="","",MONTH(A8)) | R8: Emitida | S8: Pendiente | U8: 0 | V8: =IF(B8="","",N8-U8) | W8: Auto: 30717134180_006_00001_00000617 (1).pdf | OBRA SOCIAL DEL PERSONAL DE LUZ Y FUERZA DE CORDOBA | X8: =IF(B8="","",IF(LEFT(B8,2)="NC",-1,1)) | Y8: =IF(B8="",0,N(I8)*X8) | Z8: =IF(B8="",0,N(J8)*X8) | AA8: =IF(B8="",0,N(K8)*X8) | AB8: =IF(B8="",0,N(L8)*X8) | AC8: =IF(B8="",0,N(N8)*X8)
A9: 46143 | B9: B | C9: 1 | D9: 618 | E9: OSPLYF | F9: 30565846538 | G9: Capita correspondiente al mes de Abril | H9: =IF(G9="","",IF(ISNUMBER(SEARCH("CAPITA",UPPER(G9))),651110,IF(ISNUMBER(SEARCH("REFUERZO",UPPER(G9))),651110,IF(ISNUMBER(SEARCH("VACUNACION",UPPER(G9))),651110,IF(ISNUMBER(SEARCH("ENFERMERIA",UPPER(G9))),651110,IF(ISNUMBER(SEARCH("APORTES",UPPER(G9))),651110,IF(ISNUMBER(SEARCH("HONORARIOS",UPPER(G9))),702010,IF(ISNUMBER(SEARCH("ADMINISTRACION",UPPER(G9))),702010,IF(ISNUMBER(SEARCH("GERENCIAMIENTO",UPPER(G9))),702010,IF(ISNUMBER(SEARCH("ALQUILER",UPPER(G9))),702010,IF(ISNUMBER(SEARCH("AUDITORIA",UPPER(G9))),702010,IF(ISNUMBER(SEARCH("PRESTACIONAL",UPPER(G9))),702010,702010)))))))))))) | I9: 0 | J9: 468049.54 | K9: =IF(N(I9)>0,ROUND(N(I9)*IVA_general,2),0) | L9: 0 | M9: 0 | N9: =IF(SUM(I9:M9)=0,"",SUM(I9:M9)) | O9: =IF(A9="","",TEXT(A9,"yyyy-mm")) | P9: =IF(A9="","",YEAR(A9)) | Q9: =IF(A9="","",MONTH(A9)) | R9: Emitida | S9: Pendiente | U9: 0 | V9: =IF(B9="","",N9-U9) | W9: Auto: 30717134180_006_00001_00000618 (1).pdf | OBRA SOCIAL DEL PERSONAL DE LUZ Y FUERZA DE CORDOBA | X9: =IF(B9="","",IF(LEFT(B9,2)="NC",-1,1)) | Y9: =IF(B9="",0,N(I9)*X9) | Z9: =IF(B9="",0,N(J9)*X9) | AA9: =IF(B9="",0,N(K9)*X9) | AB9: =IF(B9="",0,N(L9)*X9) | AC9: =IF(B9="",0,N(N9)*X9)
A10: 46143 | B10: B | C10: 1 | D10: 619 | E10: UOM | F10: 30585207760 | G10: Servicios medico prestacionales | H10: =IF(G10="","",IF(ISNUMBER(SEARCH("CAPITA",UPPER(G10))),651110,IF(ISNUMBER(SEARCH("REFUERZO",UPPER(G10))),651110,IF(ISNUMBER(SEARCH("VACUNACION",UPPER(G10))),651110,IF(ISNUMBER(SEARCH("ENFERMERIA",UPPER(G10))),651110,IF(ISNUMBER(SEARCH("APORTES",UPPER(G10))),651110,IF(ISNUMBER(SEARCH("HONORARIOS",UPPER(G10))),702010,IF(ISNUMBER(SEARCH("ADMINISTRACION",UPPER(G10))),702010,IF(ISNUMBER(SEARCH("GERENCIAMIENTO",UPPER(G10))),702010,IF(ISNUMBER(SEARCH("ALQUILER",UPPER(G10))),702010,IF(ISNUMBER(SEARCH("AUDITORIA",UPPER(G10))),702010,IF(ISNUMBER(SEARCH("PRESTACIONAL",UPPER(G10))),702010,702010)))))))))))) | I10: 0 | J10: 7374506.6 | K10: =IF(N(I10)>0,ROUND(N(I10)*IVA_general,2),0) | L10: 0 | M10: 0 | N10: =IF(SUM(I10:M10)=0,"",SUM(I10:M10)) | O10: =IF(A10="","",TEXT(A10,"yyyy-mm")) | P10: =IF(A10="","",YEAR(A10)) | Q10: =IF(A10="","",MONTH(A10)) | R10: Emitida | S10: Pendiente | U10: 0 | V10: =IF(B10="","",N10-U10) | W10: Auto: 30717134180_006_00001_00000619 (1).pdf | OBRA SOCIAL DE LA UNION OBRERA METALURGICA DE LA REPUBLICA A | X10: =IF(B10="","",IF(LEFT(B10,2)="NC",-1,1)) | Y10: =IF(B10="",0,N(I10)*X10) | Z10: =IF(B10="",0,N(J10)*X10) | AA10: =IF(B10="",0,N(K10)*X10) | AB10: =IF(B10="",0,N(L10)*X10) | AC10: =IF(B10="",0,N(N10)*X10)
A11: 46143 | B11: B | C11: 1 | D11: 620 | E11: OSSURRBAC | F11: 30714341746 | G11: Servicios prestacionales | H11: =IF(G11="","",IF(ISNUMBER(SEARCH("CAPITA",UPPER(G11))),651110,IF(ISNUMBER(SEARCH("REFUERZO",UPPER(G11))),651110,IF(ISNUMBER(SEARCH("VACUNACION",UPPER(G11))),651110,IF(ISNUMBER(SEARCH("ENFERMERIA",UPPER(G11))),651110,IF(ISNUMBER(SEARCH("APORTES",UPPER(G11))),651110,IF(ISNUMBER(SEARCH("HONORARIOS",UPPER(G11))),702010,IF(ISNUMBER(SEARCH("ADMINISTRACION",UPPER(G11))),702010,IF(ISNUMBER(SEARCH("GERENCIAMIENTO",UPPER(G11))),702010,IF(ISNUMBER(SEARCH("ALQUILER",UPPER(G11))),702010,IF(ISNUMBER(SEARCH("AUDITORIA",UPPER(G11))),702010,IF(ISNUMBER(SEARCH("PRESTACIONAL",UPPER(G11))),702010,702010)))))))))))) | I11: 0 | J11: 1320000 | K11: =IF(N(I11)>0,ROUND(N(I11)*IVA_general,2),0) | L11: 0 | M11: 0 | N11: =IF(SUM(I11:M11)=0,"",SUM(I11:M11)) | O11: =IF(A11="","",TEXT(A11,"yyyy-mm")) | P11: =IF(A11="","",YEAR(A11)) | Q11: =IF(A11="","",MONTH(A11)) | R11: Emitida | S11: Pendiente | U11: 0 | V11: =IF(B11="","",N11-U11) | W11: Auto: 30717134180_006_00001_00000620 (2).pdf | OBRA SOCIAL DEL SINDICATO UNICO DE RECOLECTORES DE RESIDUOS | X11: =IF(B11="","",IF(LEFT(B11,2)="NC",-1,1)) | Y11: =IF(B11="",0,N(I11)*X11) | Z11: =IF(B11="",0,N(J11)*X11) | AA11: =IF(B11="",0,N(K11)*X11) | AB11: =IF(B11="",0,N(L11)*X11) | AC11: =IF(B11="",0,N(N11)*X11)
A12: 46143 | B12: B | C12: 1 | D12: 621 | E12: OSSURRBAC | F12: 30714341746 | G12: Servicios prestacionales | H12: =IF(G12="","",IF(ISNUMBER(SEARCH("CAPITA",UPPER(G12))),651110,IF(ISNUMBER(SEARCH("REFUERZO",UPPER(G12))),651110,IF(ISNUMBER(SEARCH("VACUNACION",UPPER(G12))),651110,IF(ISNUMBER(SEARCH("ENFERMERIA",UPPER(G12))),651110,IF(ISNUMBER(SEARCH("APORTES",UPPER(G12))),651110,IF(ISNUMBER(SEARCH("HONORARIOS",UPPER(G12))),702010,IF(ISNUMBER(SEARCH("ADMINISTRACION",UPPER(G12))),702010,IF(ISNUMBER(SEARCH("GERENCIAMIENTO",UPPER(G12))),702010,IF(ISNUMBER(SEARCH("ALQUILER",UPPER(G12))),702010,IF(ISNUMBER(SEARCH("AUDITORIA",UPPER(G12))),702010,IF(ISNUMBER(SEARCH("PRESTACIONAL",UPPER(G12))),702010,702010)))))))))))) | I12: 0 | J12: 3250000 | K12: =IF(N(I12)>0,ROUND(N(I12)*IVA_general,2),0) | L12: 0 | M12: 0 | N12: =IF(SUM(I12:M12)=0,"",SUM(I12:M12)) | O12: =IF(A12="","",TEXT(A12,"yyyy-mm")) | P12: =IF(A12="","",YEAR(A12)) | Q12: =IF(A12="","",MONTH(A12)) | R12: Emitida | S12: Pendiente | U12: 0 | V12: =IF(B12="","",N12-U12) | W12: Auto: 30717134180_006_00001_00000621 (1).pdf | OBRA SOCIAL DEL SINDICATO UNICO DE RECOLECTORES DE RESIDUOS | X12: =IF(B12="","",IF(LEFT(B12,2)="NC",-1,1)) | Y12: =IF(B12="",0,N(I12)*X12) | Z12: =IF(B12="",0,N(J12)*X12) | AA12: =IF(B12="",0,N(K12)*X12) | AB12: =IF(B12="",0,N(L12)*X12) | AC12: =IF(B12="",0,N(N12)*X12)
A13: 46147 | B13: NCB | C13: 1 | D13: 56 | E13: OSPLYF | F13: 30565846538 | G13: Extra Capita_ OSPLYFC Andrada | H13: =IF(G13="","",IF(ISNUMBER(SEARCH("CAPITA",UPPER(G13))),651110,IF(ISNUMBER(SEARCH("REFUERZO",UPPER(G13))),651110,IF(ISNUMBER(SEARCH("VACUNACION",UPPER(G13))),651110,IF(ISNUMBER(SEARCH("ENFERMERIA",UPPER(G13))),651110,IF(ISNUMBER(SEARCH("APORTES",UPPER(G13))),651110,IF(ISNUMBER(SEARCH("HONORARIOS",UPPER(G13))),702010,IF(ISNUMBER(SEARCH("ADMINISTRACION",UPPER(G13))),702010,IF(ISNUMBER(SEARCH("GERENCIAMIENTO",UPPER(G13))),702010,IF(ISNUMBER(SEARCH("ALQUILER",UPPER(G13))),702010,IF(ISNUMBER(SEARCH("AUDITORIA",UPPER(G13))),702010,IF(ISNUMBER(SEARCH("PRESTACIONAL",UPPER(G13))),702010,702010)))))))))))) | I13: 0 | J13: 4585560 | K13: =IF(N(I13)>0,ROUND(N(I13)*IVA_general,2),0) | L13: 0 | M13: 0 | N13: =IF(SUM(I13:M13)=0,"",SUM(I13:M13)) | O13: =IF(A13="","",TEXT(A13,"yyyy-mm")) | P13: =IF(A13="","",YEAR(A13)) | Q13: =IF(A13="","",MONTH(A13)) | R13: Emitida | S13: Pendiente | U13: 0 | V13: =IF(B13="","",N13-U13) | W13: Auto: 30717134180_008_00001_00000056 (1).pdf | OBRA SOCIAL DEL PERSONAL DE LUZ Y FUERZA DE CORDOBA | X13: =IF(B13="","",IF(LEFT(B13,2)="NC",-1,1)) | Y13: =IF(B13="",0,N(I13)*X13) | Z13: =IF(B13="",0,N(J13)*X13) | AA13: =IF(B13="",0,N(K13)*X13) | AB13: =IF(B13="",0,N(L13)*X13) | AC13: =IF(B13="",0,N(N13)*X13)
... A25: 46153 | B25: A | C25: 1 | D25: 82 | E25: OSPIF | F25: 30661691707 | G25: Servicios medico asistenciales correspondientes | H25: =IF(G25="","",IF(ISNUMBER(SEARCH("CAPITA",UPPER(G25))),651110,IF(ISNUMBER(SEARCH("REFUERZO",UPPER(G25))),651110,IF(ISNUMBER(SEARCH("VACUNACION",UPPER(G25))),651110,IF(ISNUMBER(SEARCH("ENFERMERIA",UPPER(G25))),651110,IF(ISNUMBER(SEARCH("APORTES",UPPER(G25))),651110,IF(ISNUMBER(SEARCH("HONORARIOS",UPPER(G25))),702010,IF(ISNUMBER(SEARCH("ADMINISTRACION",UPPER(G25))),702010,IF(ISNUMBER(SEARCH("GERENCIAMIENTO",UPPER(G25))),702010,IF(ISNUMBER(SEARCH("ALQUILER",UPPER(G25))),702010,IF(ISNUMBER(SEARCH("AUDITORIA",UPPER(G25))),702010,IF(ISNUMBER(SEARCH("PRESTACIONAL",UPPER(G25))),702010,702010)))))))))))) | I25: 0 | J25: 57518139 | K25: =IF(N(I25)>0,ROUND(N(I25)*IVA_general,2),0) | L25: 0 | M25: 0 | N25: =IF(SUM(I25:M25)=0,"",SUM(I25:M25)) | O25: =IF(A25="","",TEXT(A25,"yyyy-mm")) | P25: =IF(A25="","",YEAR(A25)) | Q25: =IF(A25="","",MONTH(A25)) | R25: Emitida | S25: Pendiente | U25: 0 | V25: =IF(B25="","",N25-U25) | W25: Auto: 30717134180_001_00001_00000082.pdf | OBRA SOCIAL PARA EL PERSONAL DE LA INDUSTRIA FIDEERA | X25: =IF(B25="","",IF(LEFT(B25,2)="NC",-1,1)) | Y25: =IF(B25="",0,N(I25)*X25) | Z25: =IF(B25="",0,N(J25)*X25) | AA25: =IF(B25="",0,N(K25)*X25) | AB25: =IF(B25="",0,N(L25)*X25) | AC25: =IF(B25="",0,N(N25)*X25)
H26: =IF(G26="","",IF(ISNUMBER(SEARCH("CAPITA",UPPER(G26))),651110,IF(ISNUMBER(SEARCH("REFUERZO",UPPER(G26))),651110,IF(ISNUMBER(SEARCH("VACUNACION",UPPER(G26))),651110,IF(ISNUMBER(SEARCH("ENFERMERIA",UPPER(G26))),651110,IF(ISNUMBER(SEARCH("APORTES",UPPER(G26))),651110,IF(ISNUMBER(SEARCH("HONORARIOS",UPPER(G26))),702010,IF(ISNUMBER(SEARCH("ADMINISTRACION",UPPER(G26))),702010,IF(ISNUMBER(SEARCH("GERENCIAMIENTO",UPPER(G26))),702010,IF(ISNUMBER(SEARCH("ALQUILER",UPPER(G26))),702010,IF(ISNUMBER(SEARCH("AUDITORIA",UPPER(G26))),702010,IF(ISNUMBER(SEARCH("PRESTACIONAL",UPPER(G26))),702010,702010)))))))))))) | K26: =IF(N(I26)>0,ROUND(N(I26)*IVA_general,2),0) | L26: 0 | N26: =IF(SUM(I26:M26)=0,"",SUM(I26:M26)) | O26: =IF(A26="","",TEXT(A26,"yyyy-mm")) | P26: =IF(A26="","",YEAR(A26)) | Q26: =IF(A26="","",MONTH(A26)) | U26: 0 | V26: =IF(B26="","",N26-U26) | X26: =IF(B26="","",IF(LEFT(B26,2)="NC",-1,1)) | Y26: =IF(B26="",0,N(I26)*X26) | Z26: =IF(B26="",0,N(J26)*X26) | AA26: =IF(B26="",0,N(K26)*X26) | AB26: =IF(B26="",0,N(L26)*X26) | AC26: =IF(B26="",0,N(N26)*X26)
H27: =IF(G27="","",IF(ISNUMBER(SEARCH("CAPITA",UPPER(G27))),651110,IF(ISNUMBER(SEARCH("REFUERZO",UPPER(G27))),651110,IF(ISNUMBER(SEARCH("VACUNACION",UPPER(G27))),651110,IF(ISNUMBER(SEARCH("ENFERMERIA",UPPER(G27))),651110,IF(ISNUMBER(SEARCH("APORTES",UPPER(G27))),651110,IF(ISNUMBER(SEARCH("HONORARIOS",UPPER(G27))),702010,IF(ISNUMBER(SEARCH("ADMINISTRACION",UPPER(G27))),702010,IF(ISNUMBER(SEARCH("GERENCIAMIENTO",UPPER(G27))),702010,IF(ISNUMBER(SEARCH("ALQUILER",UPPER(G27))),702010,IF(ISNUMBER(SEARCH("AUDITORIA",UPPER(G27))),702010,IF(ISNUMBER(SEARCH("PRESTACIONAL",UPPER(G27))),702010,702010)))))))))))) | K27: =IF(N(I27)>0,ROUND(N(I27)*IVA_general,2),0) | L27: 0 | N27: =IF(SUM(I27:M27)=0,"",SUM(I27:M27)) | O27: =IF(A27="","",TEXT(A27,"yyyy-mm")) | P27: =IF(A27="","",YEAR(A27)) | Q27: =IF(A27="","",MONTH(A27)) | U27: 0 | V27: =IF(B27="","",N27-U27) | X27: =IF(B27="","",IF(LEFT(B27,2)="NC",-1,1)) | Y27: =IF(B27="",0,N(I27)*X27) | Z27: =IF(B27="",0,N(J27)*X27) | AA27: =IF(B27="",0,N(K27)*X27) | AB27: =IF(B27="",0,N(L27)*X27) | AC27: =IF(B27="",0,N(N27)*X27)
H28: =IF(G28="","",IF(ISNUMBER(SEARCH("CAPITA",UPPER(G28))),651110,IF(ISNUMBER(SEARCH("REFUERZO",UPPER(G28))),651110,IF(ISNUMBER(SEARCH("VACUNACION",UPPER(G28))),651110,IF(ISNUMBER(SEARCH("ENFERMERIA",UPPER(G28))),651110,IF(ISNUMBER(SEARCH("APORTES",UPPER(G28))),651110,IF(ISNUMBER(SEARCH("HONORARIOS",UPPER(G28))),702010,IF(ISNUMBER(SEARCH("ADMINISTRACION",UPPER(G28))),702010,IF(ISNUMBER(SEARCH("GERENCIAMIENTO",UPPER(G28))),702010,IF(ISNUMBER(SEARCH("ALQUILER",UPPER(G28))),702010,IF(ISNUMBER(SEARCH("AUDITORIA",UPPER(G28))),702010,IF(ISNUMBER(SEARCH("PRESTACIONAL",UPPER(G28))),702010,702010)))))))))))) | K28: =IF(N(I28)>0,ROUND(N(I28)*IVA_general,2),0) | L28: 0 | N28: =IF(SUM(I28:M28)=0,"",SUM(I28:M28)) | O28: =IF(A28="","",TEXT(A28,"yyyy-mm")) | P28: =IF(A28="","",YEAR(A28)) | Q28: =IF(A28="","",MONTH(A28)) | U28: 0 | V28: =IF(B28="","",N28-U28) | X28: =IF(B28="","",IF(LEFT(B28,2)="NC",-1,1)) | Y28: =IF(B28="",0,N(I28)*X28) | Z28: =IF(B28="",0,N(J28)*X28) | AA28: =IF(B28="",0,N(K28)*X28) | AB28: =IF(B28="",0,N(L28)*X28) | AC28: =IF(B28="",0,N(N28)*X28)
H29: =IF(G29="","",IF(ISNUMBER(SEARCH("CAPITA",UPPER(G29))),651110,IF(ISNUMBER(SEARCH("REFUERZO",UPPER(G29))),651110,IF(ISNUMBER(SEARCH("VACUNACION",UPPER(G29))),651110,IF(ISNUMBER(SEARCH("ENFERMERIA",UPPER(G29))),651110,IF(ISNUMBER(SEARCH("APORTES",UPPER(G29))),651110,IF(ISNUMBER(SEARCH("HONORARIOS",UPPER(G29))),702010,IF(ISNUMBER(SEARCH("ADMINISTRACION",UPPER(G29))),702010,IF(ISNUMBER(SEARCH("GERENCIAMIENTO",UPPER(G29))),702010,IF(ISNUMBER(SEARCH("ALQUILER",UPPER(G29))),702010,IF(ISNUMBER(SEARCH("AUDITORIA",UPPER(G29))),702010,IF(ISNUMBER(SEARCH("PRESTACIONAL",UPPER(G29))),702010,702010)))))))))))) | K29: =IF(N(I29)>0,ROUND(N(I29)*IVA_general,2),0) | L29: 0 | N29: =IF(SUM(I29:M29)=0,"",SUM(I29:M29)) | O29: =IF(A29="","",TEXT(A29,"yyyy-mm")) | P29: =IF(A29="","",YEAR(A29)) | Q29: =IF(A29="","",MONTH(A29)) | U29: 0 | V29: =IF(B29="","",N29-U29) | X29: =IF(B29="","",IF(LEFT(B29,2)="NC",-1,1)) | Y29: =IF(B29="",0,N(I29)*X29) | Z29: =IF(B29="",0,N(J29)*X29) | AA29: =IF(B29="",0,N(K29)*X29) | AB29: =IF(B29="",0,N(L29)*X29) | AC29: =IF(B29="",0,N(N29)*X29)
H30: =IF(G30="","",IF(ISNUMBER(SEARCH("CAPITA",UPPER(G30))),651110,IF(ISNUMBER(SEARCH("REFUERZO",UPPER(G30))),651110,IF(ISNUMBER(SEARCH("VACUNACION",UPPER(G30))),651110,IF(ISNUMBER(SEARCH("ENFERMERIA",UPPER(G30))),651110,IF(ISNUMBER(SEARCH("APORTES",UPPER(G30))),651110,IF(ISNUMBER(SEARCH("HONORARIOS",UPPER(G30))),702010,IF(ISNUMBER(SEARCH("ADMINISTRACION",UPPER(G30))),702010,IF(ISNUMBER(SEARCH("GERENCIAMIENTO",UPPER(G30))),702010,IF(ISNUMBER(SEARCH("ALQUILER",UPPER(G30))),702010,IF(ISNUMBER(SEARCH("AUDITORIA",UPPER(G30))),702010,IF(ISNUMBER(SEARCH("PRESTACIONAL",UPPER(G30))),702010,702010)))))))))))) | K30: =IF(N(I30)>0,ROUND(N(I30)*IVA_general,2),0) | L30: 0 | N30: =IF(SUM(I30:M30)=0,"",SUM(I30:M30)) | O30: =IF(A30="","",TEXT(A30,"yyyy-mm")) | P30: =IF(A30="","",YEAR(A30)) | Q30: =IF(A30="","",MONTH(A30)) | U30: 0 | V30: =IF(B30="","",N30-U30) | X30: =IF(B30="","",IF(LEFT(B30,2)="NC",-1,1)) | Y30: =IF(B30="",0,N(I30)*X30) | Z30: =IF(B30="",0,N(J30)*X30) | AA30: =IF(B30="",0,N(K30)*X30) | AB30: =IF(B30="",0,N(L30)*X30) | AC30: =IF(B30="",0,N(N30)*X30)
H31: =IF(G31="","",IF(ISNUMBER(SEARCH("CAPITA",UPPER(G31))),651110,IF(ISNUMBER(SEARCH("REFUERZO",UPPER(G31))),651110,IF(ISNUMBER(SEARCH("VACUNACION",UPPER(G31))),651110,IF(ISNUMBER(SEARCH("ENFERMERIA",UPPER(G31))),651110,IF(ISNUMBER(SEARCH("APORTES",UPPER(G31))),651110,IF(ISNUMBER(SEARCH("HONORARIOS",UPPER(G31))),702010,IF(ISNUMBER(SEARCH("ADMINISTRACION",UPPER(G31))),702010,IF(ISNUMBER(SEARCH("GERENCIAMIENTO",UPPER(G31))),702010,IF(ISNUMBER(SEARCH("ALQUILER",UPPER(G31))),702010,IF(ISNUMBER(SEARCH("AUDITORIA",UPPER(G31))),702010,IF(ISNUMBER(SEARCH("PRESTACIONAL",UPPER(G31))),702010,702010)))))))))))) | K31: =IF(N(I31)>0,ROUND(N(I31)*IVA_general,2),0) | L31: 0 | N31: =IF(SUM(I31:M31)=0,"",SUM(I31:M31)) | O31: =IF(A31="","",TEXT(A31,"yyyy-mm")) | P31: =IF(A31="","",YEAR(A31)) | Q31: =IF(A31="","",MONTH(A31)) | U31: 0 | V31: =IF(B31="","",N31-U31) | X31: =IF(B31="","",IF(LEFT(B31,2)="NC",-1,1)) | Y31: =IF(B31="",0,N(I31)*X31) | Z31: =IF(B31="",0,N(J31)*X31) | AA31: =IF(B31="",0,N(K31)*X31) | AB31: =IF(B31="",0,N(L31)*X31) | AC31: =IF(B31="",0,N(N31)*X31)
H32: =IF(G32="","",IF(ISNUMBER(SEARCH("CAPITA",UPPER(G32))),651110,IF(ISNUMBER(SEARCH("REFUERZO",UPPER(G32))),651110,IF(ISNUMBER(SEARCH("VACUNACION",UPPER(G32))),651110,IF(ISNUMBER(SEARCH("ENFERMERIA",UPPER(G32))),651110,IF(ISNUMBER(SEARCH("APORTES",UPPER(G32))),651110,IF(ISNUMBER(SEARCH("HONORARIOS",UPPER(G32))),702010,IF(ISNUMBER(SEARCH("ADMINISTRACION",UPPER(G32))),702010,IF(ISNUMBER(SEARCH("GERENCIAMIENTO",UPPER(G32))),702010,IF(ISNUMBER(SEARCH("ALQUILER",UPPER(G32))),702010,IF(ISNUMBER(SEARCH("AUDITORIA",UPPER(G32))),702010,IF(ISNUMBER(SEARCH("PRESTACIONAL",UPPER(G32))),702010,702010)))))))))))) | K32: =IF(N(I32)>0,ROUND(N(I32)*IVA_general,2),0) | L32: 0 | N32: =IF(SUM(I32:M32)=0,"",SUM(I32:M32)) | O32: =IF(A32="","",TEXT(A32,"yyyy-mm")) | P32: =IF(A32="","",YEAR(A32)) | Q32: =IF(A32="","",MONTH(A32)) | U32: 0 | V32: =IF(B32="","",N32-U32) | X32: =IF(B32="","",IF(LEFT(B32,2)="NC",-1,1)) | Y32: =IF(B32="",0,N(I32)*X32) | Z32: =IF(B32="",0,N(J32)*X32) | AA32: =IF(B32="",0,N(K32)*X32) | AB32: =IF(B32="",0,N(L32)*X32) | AC32: =IF(B32="",0,N(N32)*X32)
H33: =IF(G33="","",IF(ISNUMBER(SEARCH("CAPITA",UPPER(G33))),651110,IF(ISNUMBER(SEARCH("REFUERZO",UPPER(G33))),651110,IF(ISNUMBER(SEARCH("VACUNACION",UPPER(G33))),651110,IF(ISNUMBER(SEARCH("ENFERMERIA",UPPER(G33))),651110,IF(ISNUMBER(SEARCH("APORTES",UPPER(G33))),651110,IF(ISNUMBER(SEARCH("HONORARIOS",UPPER(G33))),702010,IF(ISNUMBER(SEARCH("ADMINISTRACION",UPPER(G33))),702010,IF(ISNUMBER(SEARCH("GERENCIAMIENTO",UPPER(G33))),702010,IF(ISNUMBER(SEARCH("ALQUILER",UPPER(G33))),702010,IF(ISNUMBER(SEARCH("AUDITORIA",UPPER(G33))),702010,IF(ISNUMBER(SEARCH("PRESTACIONAL",UPPER(G33))),702010,702010)))))))))))) | K33: =IF(N(I33)>0,ROUND(N(I33)*IVA_general,2),0) | L33: 0 | N33: =IF(SUM(I33:M33)=0,"",SUM(I33:M33)) | O33: =IF(A33="","",TEXT(A33,"yyyy-mm")) | P33: =IF(A33="","",YEAR(A33)) | Q33: =IF(A33="","",MONTH(A33)) | U33: 0 | V33: =IF(B33="","",N33-U33) | X33: =IF(B33="","",IF(LEFT(B33,2)="NC",-1,1)) | Y33: =IF(B33="",0,N(I33)*X33) | Z33: =IF(B33="",0,N(J33)*X33) | AA33: =IF(B33="",0,N(K33)*X33) | AB33: =IF(B33="",0,N(L33)*X33) | AC33: =IF(B33="",0,N(N33)*X33)
H34: =IF(G34="","",IF(ISNUMBER(SEARCH("CAPITA",UPPER(G34))),651110,IF(ISNUMBER(SEARCH("REFUERZO",UPPER(G34))),651110,IF(ISNUMBER(SEARCH("VACUNACION",UPPER(G34))),651110,IF(ISNUMBER(SEARCH("ENFERMERIA",UPPER(G34))),651110,IF(ISNUMBER(SEARCH("APORTES",UPPER(G34))),651110,IF(ISNUMBER(SEARCH("HONORARIOS",UPPER(G34))),702010,IF(ISNUMBER(SEARCH("ADMINISTRACION",UPPER(G34))),702010,IF(ISNUMBER(SEARCH("GERENCIAMIENTO",UPPER(G34))),702010,IF(ISNUMBER(SEARCH("ALQUILER",UPPER(G34))),702010,IF(ISNUMBER(SEARCH("AUDITORIA",UPPER(G34))),702010,IF(ISNUMBER(SEARCH("PRESTACIONAL",UPPER(G34))),702010,702010)))))))))))) | K34: =IF(N(I34)>0,ROUND(N(I34)*IVA_general,2),0) | L34: 0 | N34: =IF(SUM(I34:M34)=0,"",SUM(I34:M34)) | O34: =IF(A34="","",TEXT(A34,"yyyy-mm")) | P34: =IF(A34="","",YEAR(A34)) | Q34: =IF(A34="","",MONTH(A34)) | U34: 0 | V34: =IF(B34="","",N34-U34) | X34: =IF(B34="","",IF(LEFT(B34,2)="NC",-1,1)) | Y34: =IF(B34="",0,N(I34)*X34) | Z34: =IF(B34="",0,N(J34)*X34) | AA34: =IF(B34="",0,N(K34)*X34) | AB34: =IF(B34="",0,N(L34)*X34) | AC34: =IF(B34="",0,N(N34)*X34)
H35: =IF(G35="","",IF(ISNUMBER(SEARCH("CAPITA",UPPER(G35))),651110,IF(ISNUMBER(SEARCH("REFUERZO",UPPER(G35))),651110,IF(ISNUMBER(SEARCH("VACUNACION",UPPER(G35))),651110,IF(ISNUMBER(SEARCH("ENFERMERIA",UPPER(G35))),651110,IF(ISNUMBER(SEARCH("APORTES",UPPER(G35))),651110,IF(ISNUMBER(SEARCH("HONORARIOS",UPPER(G35))),702010,IF(ISNUMBER(SEARCH("ADMINISTRACION",UPPER(G35))),702010,IF(ISNUMBER(SEARCH("GERENCIAMIENTO",UPPER(G35))),702010,IF(ISNUMBER(SEARCH("ALQUILER",UPPER(G35))),702010,IF(ISNUMBER(SEARCH("AUDITORIA",UPPER(G35))),702010,IF(ISNUMBER(SEARCH("PRESTACIONAL",UPPER(G35))),702010,702010)))))))))))) | K35: =IF(N(I35)>0,ROUND(N(I35)*IVA_general,2),0) | L35: 0 | N35: =IF(SUM(I35:M35)=0,"",SUM(I35:M35)) | O35: =IF(A35="","",TEXT(A35,"yyyy-mm")) | P35: =IF(A35="","",YEAR(A35)) | Q35: =IF(A35="","",MONTH(A35)) | U35: 0 | V35: =IF(B35="","",N35-U35) | X35: =IF(B35="","",IF(LEFT(B35,2)="NC",-1,1)) | Y35: =IF(B35="",0,N(I35)*X35) | Z35: =IF(B35="",0,N(J35)*X35) | AA35: =IF(B35="",0,N(K35)*X35) | AB35: =IF(B35="",0,N(L35)*X35) | AC35: =IF(B35="",0,N(N35)*X35)
H36: =IF(G36="","",IF(ISNUMBER(SEARCH("CAPITA",UPPER(G36))),651110,IF(ISNUMBER(SEARCH("REFUERZO",UPPER(G36))),651110,IF(ISNUMBER(SEARCH("VACUNACION",UPPER(G36))),651110,IF(ISNUMBER(SEARCH("ENFERMERIA",UPPER(G36))),651110,IF(ISNUMBER(SEARCH("APORTES",UPPER(G36))),651110,IF(ISNUMBER(SEARCH("HONORARIOS",UPPER(G36))),702010,IF(ISNUMBER(SEARCH("ADMINISTRACION",UPPER(G36))),702010,IF(ISNUMBER(SEARCH("GERENCIAMIENTO",UPPER(G36))),702010,IF(ISNUMBER(SEARCH("ALQUILER",UPPER(G36))),702010,IF(ISNUMBER(SEARCH("AUDITORIA",UPPER(G36))),702010,IF(ISNUMBER(SEARCH("PRESTACIONAL",UPPER(G36))),702010,702010)))))))))))) | K36: =IF(N(I36)>0,ROUND(N(I36)*IVA_general,2),0) | L36: 0 | N36: =IF(SUM(I36:M36)=0,"",SUM(I36:M36)) | O36: =IF(A36="","",TEXT(A36,"yyyy-mm")) | P36: =IF(A36="","",YEAR(A36)) | Q36: =IF(A36="","",MONTH(A36)) | U36: 0 | V36: =IF(B36="","",N36-U36) | X36: =IF(B36="","",IF(LEFT(B36,2)="NC",-1,1)) | Y36: =IF(B36="",0,N(I36)*X36) | Z36: =IF(B36="",0,N(J36)*X36) | AA36: =IF(B36="",0,N(K36)*X36) | AB36: =IF(B36="",0,N(L36)*X36) | AC36: =IF(B36="",0,N(N36)*X36)
H37: =IF(G37="","",IF(ISNUMBER(SEARCH("CAPITA",UPPER(G37))),651110,IF(ISNUMBER(SEARCH("REFUERZO",UPPER(G37))),651110,IF(ISNUMBER(SEARCH("VACUNACION",UPPER(G37))),651110,IF(ISNUMBER(SEARCH("ENFERMERIA",UPPER(G37))),651110,IF(ISNUMBER(SEARCH("APORTES",UPPER(G37))),651110,IF(ISNUMBER(SEARCH("HONORARIOS",UPPER(G37))),702010,IF(ISNUMBER(SEARCH("ADMINISTRACION",UPPER(G37))),702010,IF(ISNUMBER(SEARCH("GERENCIAMIENTO",UPPER(G37))),702010,IF(ISNUMBER(SEARCH("ALQUILER",UPPER(G37))),702010,IF(ISNUMBER(SEARCH("AUDITORIA",UPPER(G37))),702010,IF(ISNUMBER(SEARCH("PRESTACIONAL",UPPER(G37))),702010,702010)))))))))))) | K37: =IF(N(I37)>0,ROUND(N(I37)*IVA_general,2),0) | L37: 0 | N37: =IF(SUM(I37:M37)=0,"",SUM(I37:M37)) | O37: =IF(A37="","",TEXT(A37,"yyyy-mm")) | P37: =IF(A37="","",YEAR(A37)) | Q37: =IF(A37="","",MONTH(A37)) | U37: 0 | V37: =IF(B37="","",N37-U37) | X37: =IF(B37="","",IF(LEFT(B37,2)="NC",-1,1)) | Y37: =IF(B37="",0,N(I37)*X37) | Z37: =IF(B37="",0,N(J37)*X37) | AA37: =IF(B37="",0,N(K37)*X37) | AB37: =IF(B37="",0,N(L37)*X37) | AC37: =IF(B37="",0,N(N37)*X37)
... H501: =IF(G501="","",IF(ISNUMBER(SEARCH("CAPITA",UPPER(G501))),651110,IF(ISNUMBER(SEARCH("REFUERZO",UPPER(G501))),651110,IF(ISNUMBER(SEARCH("VACUNACION",UPPER(G501))),651110,IF(ISNUMBER(SEARCH("ENFERMERIA",UPPER(G501))),651110,IF(ISNUMBER(SEARCH("APORTES",UPPER(G501))),651110,IF(ISNUMBER(SEARCH("HONORARIOS",UPPER(G501))),702010,IF(ISNUMBER(SEARCH("ADMINISTRACION",UPPER(G501))),702010,IF(ISNUMBER(SEARCH("GERENCIAMIENTO",UPPER(G501))),702010,IF(ISNUMBER(SEARCH("ALQUILER",UPPER(G501))),702010,IF(ISNUMBER(SEARCH("AUDITORIA",UPPER(G501))),702010,IF(ISNUMBER(SEARCH("PRESTACIONAL",UPPER(G501))),702010,702010)))))))))))) | K501: =IF(N(I501)>0,ROUND(N(I501)*IVA_general,2),0) | L501: 0 | N501: =IF(SUM(I501:M501)=0,"",SUM(I501:M501)) | O501: =IF(A501="","",TEXT(A501,"yyyy-mm")) | P501: =IF(A501="","",YEAR(A501)) | Q501: =IF(A501="","",MONTH(A501)) | U501: 0 | V501: =IF(B501="","",N501-U501) | X501: =IF(B501="","",IF(LEFT(B501,2)="NC",-1,1)) | Y501: =IF(B501="",0,N(I501)*X501) | Z501: =IF(B501="",0,N(J501)*X501) | AA501: =IF(B501="",0,N(K501)*X501) | AB501: =IF(B501="",0,N(L501)*X501) | AC501: =IF(B501="",0,N(N501)*X501)

Sheet Checklist
A1: CHECKLIST DE FACTURACIÓN MENSUAL - 2026
A2: Cliente | B2: Concepto | C2: Activ. | D2: Ene | E2: Feb | F2: Mar | G2: Abr | H2: May | I2: Jun | J2: Jul | K2: Ago | L2: Sep | M2: Oct | N2: Nov | O2: Dic | P2: Total Año | Q2: % Compl.
A3: OSPLYF | B3: Cápitas + Honorarios + Extras | C3: multi | D3: =SUMIFS(Fac_Total,Fac_Cliente,$A3,Fac_Mes,1,Fac_Anio,2026,Fac_EstadoAFIP,"<>Anulada") | E3: =SUMIFS(Fac_Total,Fac_Cliente,$A3,Fac_Mes,2,Fac_Anio,2026,Fac_EstadoAFIP,"<>Anulada") | F3: =SUMIFS(Fac_Total,Fac_Cliente,$A3,Fac_Mes,3,Fac_Anio,2026,Fac_EstadoAFIP,"<>Anulada") | G3: =SUMIFS(Fac_Total,Fac_Cliente,$A3,Fac_Mes,4,Fac_Anio,2026,Fac_EstadoAFIP,"<>Anulada") | H3: =SUMIFS(Fac_Total,Fac_Cliente,$A3,Fac_Mes,5,Fac_Anio,2026,Fac_EstadoAFIP,"<>Anulada") | I3: =SUMIFS(Fac_Total,Fac_Cliente,$A3,Fac_Mes,6,Fac_Anio,2026,Fac_EstadoAFIP,"<>Anulada") | J3: =SUMIFS(Fac_Total,Fac_Cliente,$A3,Fac_Mes,7,Fac_Anio,2026,Fac_EstadoAFIP,"<>Anulada") | K3: =SUMIFS(Fac_Total,Fac_Cliente,$A3,Fac_Mes,8,Fac_Anio,2026,Fac_EstadoAFIP,"<>Anulada") | L3: =SUMIFS(Fac_Total,Fac_Cliente,$A3,Fac_Mes,9,Fac_Anio,2026,Fac_EstadoAFIP,"<>Anulada") | M3: =SUMIFS(Fac_Total,Fac_Cliente,$A3,Fac_Mes,10,Fac_Anio,2026,Fac_EstadoAFIP,"<>Anulada") | N3: =SUMIFS(Fac_Total,Fac_Cliente,$A3,Fac_Mes,11,Fac_Anio,2026,Fac_EstadoAFIP,"<>Anulada") | O3: =SUMIFS(Fac_Total,Fac_Cliente,$A3,Fac_Mes,12,Fac_Anio,2026,Fac_EstadoAFIP,"<>Anulada") | P3: =SUM(D3:O3) | Q3: =COUNTIF(D3:O3,">0")/12
A4: OSSURRBAC | B4: Cápita + Alquiler ecógrafo + Servicios | C4: multi | D4: =SUMIFS(Fac_Total,Fac_Cliente,$A4,Fac_Mes,1,Fac_Anio,2026,Fac_EstadoAFIP,"<>Anulada") | E4: =SUMIFS(Fac_Total,Fac_Cliente,$A4,Fac_Mes,2,Fac_Anio,2026,Fac_EstadoAFIP,"<>Anulada") | F4: =SUMIFS(Fac_Total,Fac_Cliente,$A4,Fac_Mes,3,Fac_Anio,2026,Fac_EstadoAFIP,"<>Anulada") | G4: =SUMIFS(Fac_Total,Fac_Cliente,$A4,Fac_Mes,4,Fac_Anio,2026,Fac_EstadoAFIP,"<>Anulada") | H4: =SUMIFS(Fac_Total,Fac_Cliente,$A4,Fac_Mes,5,Fac_Anio,2026,Fac_EstadoAFIP,"<>Anulada") | I4: =SUMIFS(Fac_Total,Fac_Cliente,$A4,Fac_Mes,6,Fac_Anio,2026,Fac_EstadoAFIP,"<>Anulada") | J4: =SUMIFS(Fac_Total,Fac_Cliente,$A4,Fac_Mes,7,Fac_Anio,2026,Fac_EstadoAFIP,"<>Anulada") | K4: =SUMIFS(Fac_Total,Fac_Cliente,$A4,Fac_Mes,8,Fac_Anio,2026,Fac_EstadoAFIP,"<>Anulada") | L4: =SUMIFS(Fac_Total,Fac_Cliente,$A4,Fac_Mes,9,Fac_Anio,2026,Fac_EstadoAFIP,"<>Anulada") | M4: =SUMIFS(Fac_Total,Fac_Cliente,$A4,Fac_Mes,10,Fac_Anio,2026,Fac_EstadoAFIP,"<>Anulada") | N4: =SUMIFS(Fac_Total,Fac_Cliente,$A4,Fac_Mes,11,Fac_Anio,2026,Fac_EstadoAFIP,"<>Anulada") | O4: =SUMIFS(Fac_Total,Fac_Cliente,$A4,Fac_Mes,12,Fac_Anio,2026,Fac_EstadoAFIP,"<>Anulada") | P4: =SUM(D4:O4) | Q4: =COUNTIF(D4:O4,">0")/12
A5: AMSURRBAC | B5: Cápitas vacunación + enfermería | C5: multi | D5: =SUMIFS(Fac_Total,Fac_Cliente,$A5,Fac_Mes,1,Fac_Anio,2026,Fac_EstadoAFIP,"<>Anulada") | E5: =SUMIFS(Fac_Total,Fac_Cliente,$A5,Fac_Mes,2,Fac_Anio,2026,Fac_EstadoAFIP,"<>Anulada") | F5: =SUMIFS(Fac_Total,Fac_Cliente,$A5,Fac_Mes,3,Fac_Anio,2026,Fac_EstadoAFIP,"<>Anulada") | G5: =SUMIFS(Fac_Total,Fac_Cliente,$A5,Fac_Mes,4,Fac_Anio,2026,Fac_EstadoAFIP,"<>Anulada") | H5: =SUMIFS(Fac_Total,Fac_Cliente,$A5,Fac_Mes,5,Fac_Anio,2026,Fac_EstadoAFIP,"<>Anulada") | I5: =SUMIFS(Fac_Total,Fac_Cliente,$A5,Fac_Mes,6,Fac_Anio,2026,Fac_EstadoAFIP,"<>Anulada") | J5: =SUMIFS(Fac_Total,Fac_Cliente,$A5,Fac_Mes,7,Fac_Anio,2026,Fac_EstadoAFIP,"<>Anulada") | K5: =SUMIFS(Fac_Total,Fac_Cliente,$A5,Fac_Mes,8,Fac_Anio,2026,Fac_EstadoAFIP,"<>Anulada") | L5: =SUMIFS(Fac_Total,Fac_Cliente,$A5,Fac_Mes,9,Fac_Anio,2026,Fac_EstadoAFIP,"<>Anulada") | M5: =SUMIFS(Fac_Total,Fac_Cliente,$A5,Fac_Mes,10,Fac_Anio,2026,Fac_EstadoAFIP,"<>Anulada") | N5: =SUMIFS(Fac_Total,Fac_Cliente,$A5,Fac_Mes,11,Fac_Anio,2026,Fac_EstadoAFIP,"<>Anulada") | O5: =SUMIFS(Fac_Total,Fac_Cliente,$A5,Fac_Mes,12,Fac_Anio,2026,Fac_EstadoAFIP,"<>Anulada") | P5: =SUM(D5:O5) | Q5: =COUNTIF(D5:O5,">0")/12
A6: OSPEVIC | B6: Cápita + Extra cápita | C6: multi | D6: =SUMIFS(Fac_Total,Fac_Cliente,$A6,Fac_Mes,1,Fac_Anio,2026,Fac_EstadoAFIP,"<>Anulada") | E6: =SUMIFS(Fac_Total,Fac_Cliente,$A6,Fac_Mes,2,Fac_Anio,2026,Fac_EstadoAFIP,"<>Anulada") | F6: =SUMIFS(Fac_Total,Fac_Cliente,$A6,Fac_Mes,3,Fac_Anio,2026,Fac_EstadoAFIP,"<>Anulada") | G6: =SUMIFS(Fac_Total,Fac_Cliente,$A6,Fac_Mes,4,Fac_Anio,2026,Fac_EstadoAFIP,"<>Anulada") | H6: =SUMIFS(Fac_Total,Fac_Cliente,$A6,Fac_Mes,5,Fac_Anio,2026,Fac_EstadoAFIP,"<>Anulada") | I6: =SUMIFS(Fac_Total,Fac_Cliente,$A6,Fac_Mes,6,Fac_Anio,2026,Fac_EstadoAFIP,"<>Anulada") | J6: =SUMIFS(Fac_Total,Fac_Cliente,$A6,Fac_Mes,7,Fac_Anio,2026,Fac_EstadoAFIP,"<>Anulada") | K6: =SUMIFS(Fac_Total,Fac_Cliente,$A6,Fac_Mes,8,Fac_Anio,2026,Fac_EstadoAFIP,"<>Anulada") | L6: =SUMIFS(Fac_Total,Fac_Cliente,$A6,Fac_Mes,9,Fac_Anio,2026,Fac_EstadoAFIP,"<>Anulada") | M6: =SUMIFS(Fac_Total,Fac_Cliente,$A6,Fac_Mes,10,Fac_Anio,2026,Fac_EstadoAFIP,"<>Anulada") | N6: =SUMIFS(Fac_Total,Fac_Cliente,$A6,Fac_Mes,11,Fac_Anio,2026,Fac_EstadoAFIP,"<>Anulada") | O6: =SUMIFS(Fac_Total,Fac_Cliente,$A6,Fac_Mes,12,Fac_Anio,2026,Fac_EstadoAFIP,"<>Anulada") | P6: =SUM(D6:O6) | Q6: =COUNTIF(D6:O6,">0")/12
A7: OSPIF | B7: Cápita + Honorarios + Aportes | C7: multi | D7: =SUMIFS(Fac_Total,Fac_Cliente,$A7,Fac_Mes,1,Fac_Anio,2026,Fac_EstadoAFIP,"<>Anulada") | E7: =SUMIFS(Fac_Total,Fac_Cliente,$A7,Fac_Mes,2,Fac_Anio,2026,Fac_EstadoAFIP,"<>Anulada") | F7: =SUMIFS(Fac_Total,Fac_Cliente,$A7,Fac_Mes,3,Fac_Anio,2026,Fac_EstadoAFIP,"<>Anulada") | G7: =SUMIFS(Fac_Total,Fac_Cliente,$A7,Fac_Mes,4,Fac_Anio,2026,Fac_EstadoAFIP,"<>Anulada") | H7: =SUMIFS(Fac_Total,Fac_Cliente,$A7,Fac_Mes,5,Fac_Anio,2026,Fac_EstadoAFIP,"<>Anulada") | I7: =SUMIFS(Fac_Total,Fac_Cliente,$A7,Fac_Mes,6,Fac_Anio,2026,Fac_EstadoAFIP,"<>Anulada") | J7: =SUMIFS(Fac_Total,Fac_Cliente,$A7,Fac_Mes,7,Fac_Anio,2026,Fac_EstadoAFIP,"<>Anulada") | K7: =SUMIFS(Fac_Total,Fac_Cliente,$A7,Fac_Mes,8,Fac_Anio,2026,Fac_EstadoAFIP,"<>Anulada") | L7: =SUMIFS(Fac_Total,Fac_Cliente,$A7,Fac_Mes,9,Fac_Anio,2026,Fac_EstadoAFIP,"<>Anulada") | M7: =SUMIFS(Fac_Total,Fac_Cliente,$A7,Fac_Mes,10,Fac_Anio,2026,Fac_EstadoAFIP,"<>Anulada") | N7: =SUMIFS(Fac_Total,Fac_Cliente,$A7,Fac_Mes,11,Fac_Anio,2026,Fac_EstadoAFIP,"<>Anulada") | O7: =SUMIFS(Fac_Total,Fac_Cliente,$A7,Fac_Mes,12,Fac_Anio,2026,Fac_EstadoAFIP,"<>Anulada") | P7: =SUM(D7:O7) | Q7: =COUNTIF(D7:O7,">0")/12
A8: UOM | B8: Servicios médicos prestacionales | C8: multi | D8: =SUMIFS(Fac_Total,Fac_Cliente,$A8,Fac_Mes,1,Fac_Anio,2026,Fac_EstadoAFIP,"<>Anulada") | E8: =SUMIFS(Fac_Total,Fac_Cliente,$A8,Fac_Mes,2,Fac_Anio,2026,Fac_EstadoAFIP,"<>Anulada") | F8: =SUMIFS(Fac_Total,Fac_Cliente,$A8,Fac_Mes,3,Fac_Anio,2026,Fac_EstadoAFIP,"<>Anulada") | G8: =SUMIFS(Fac_Total,Fac_Cliente,$A8,Fac_Mes,4,Fac_Anio,2026,Fac_EstadoAFIP,"<>Anulada") | H8: =SUMIFS(Fac_Total,Fac_Cliente,$A8,Fac_Mes,5,Fac_Anio,2026,Fac_EstadoAFIP,"<>Anulada") | I8: =SUMIFS(Fac_Total,Fac_Cliente,$A8,Fac_Mes,6,Fac_Anio,2026,Fac_EstadoAFIP,"<>Anulada") | J8: =SUMIFS(Fac_Total,Fac_Cliente,$A8,Fac_Mes,7,Fac_Anio,2026,Fac_EstadoAFIP,"<>Anulada") | K8: =SUMIFS(Fac_Total,Fac_Cliente,$A8,Fac_Mes,8,Fac_Anio,2026,Fac_EstadoAFIP,"<>Anulada") | L8: =SUMIFS(Fac_Total,Fac_Cliente,$A8,Fac_Mes,9,Fac_Anio,2026,Fac_EstadoAFIP,"<>Anulada") | M8: =SUMIFS(Fac_Total,Fac_Cliente,$A8,Fac_Mes,10,Fac_Anio,2026,Fac_EstadoAFIP,"<>Anulada") | N8: =SUMIFS(Fac_Total,Fac_Cliente,$A8,Fac_Mes,11,Fac_Anio,2026,Fac_EstadoAFIP,"<>Anulada") | O8: =SUMIFS(Fac_Total,Fac_Cliente,$A8,Fac_Mes,12,Fac_Anio,2026,Fac_EstadoAFIP,"<>Anulada") | P8: =SUM(D8:O8) | Q8: =COUNTIF(D8:O8,">0")/12
A9: MOSAISTAS | B9: Honorarios | C9: multi | D9: =SUMIFS(Fac_Total,Fac_Cliente,$A9,Fac_Mes,1,Fac_Anio,2026,Fac_EstadoAFIP,"<>Anulada") | E9: =SUMIFS(Fac_Total,Fac_Cliente,$A9,Fac_Mes,2,Fac_Anio,2026,Fac_EstadoAFIP,"<>Anulada") | F9: =SUMIFS(Fac_Total,Fac_Cliente,$A9,Fac_Mes,3,Fac_Anio,2026,Fac_EstadoAFIP,"<>Anulada") | G9: =SUMIFS(Fac_Total,Fac_Cliente,$A9,Fac_Mes,4,Fac_Anio,2026,Fac_EstadoAFIP,"<>Anulada") | H9: =SUMIFS(Fac_Total,Fac_Cliente,$A9,Fac_Mes,5,Fac_Anio,2026,Fac_EstadoAFIP,"<>Anulada") | I9: =SUMIFS(Fac_Total,Fac_Cliente,$A9,Fac_Mes,6,Fac_Anio,2026,Fac_EstadoAFIP,"<>Anulada") | J9: =SUMIFS(Fac_Total,Fac_Cliente,$A9,Fac_Mes,7,Fac_Anio,2026,Fac_EstadoAFIP,"<>Anulada") | K9: =SUMIFS(Fac_Total,Fac_Cliente,$A9,Fac_Mes,8,Fac_Anio,2026,Fac_EstadoAFIP,"<>Anulada") | L9: =SUMIFS(Fac_Total,Fac_Cliente,$A9,Fac_Mes,9,Fac_Anio,2026,Fac_EstadoAFIP,"<>Anulada") | M9: =SUMIFS(Fac_Total,Fac_Cliente,$A9,Fac_Mes,10,Fac_Anio,2026,Fac_EstadoAFIP,"<>Anulada") | N9: =SUMIFS(Fac_Total,Fac_Cliente,$A9,Fac_Mes,11,Fac_Anio,2026,Fac_EstadoAFIP,"<>Anulada") | O9: =SUMIFS(Fac_Total,Fac_Cliente,$A9,Fac_Mes,12,Fac_Anio,2026,Fac_EstadoAFIP,"<>Anulada") | P9: =SUM(D9:O9) | Q9: =COUNTIF(D9:O9,">0")/12
A10: FUNDACION BIENESTAR SIRELYF | B10: Servicios prestacionales | C10: multi | D10: =SUMIFS(Fac_Total,Fac_Cliente,$A10,Fac_Mes,1,Fac_Anio,2026,Fac_EstadoAFIP,"<>Anulada") | E10: =SUMIFS(Fac_Total,Fac_Cliente,$A10,Fac_Mes,2,Fac_Anio,2026,Fac_EstadoAFIP,"<>Anulada") | F10: =SUMIFS(Fac_Total,Fac_Cliente,$A10,Fac_Mes,3,Fac_Anio,2026,Fac_EstadoAFIP,"<>Anulada") | G10: =SUMIFS(Fac_Total,Fac_Cliente,$A10,Fac_Mes,4,Fac_Anio,2026,Fac_EstadoAFIP,"<>Anulada") | H10: =SUMIFS(Fac_Total,Fac_Cliente,$A10,Fac_Mes,5,Fac_Anio,2026,Fac_EstadoAFIP,"<>Anulada") | I10: =SUMIFS(Fac_Total,Fac_Cliente,$A10,Fac_Mes,6,Fac_Anio,2026,Fac_EstadoAFIP,"<>Anulada") | J10: =SUMIFS(Fac_Total,Fac_Cliente,$A10,Fac_Mes,7,Fac_Anio,2026,Fac_EstadoAFIP,"<>Anulada") | K10: =SUMIFS(Fac_Total,Fac_Cliente,$A10,Fac_Mes,8,Fac_Anio,2026,Fac_EstadoAFIP,"<>Anulada") | L10: =SUMIFS(Fac_Total,Fac_Cliente,$A10,Fac_Mes,9,Fac_Anio,2026,Fac_EstadoAFIP,"<>Anulada") | M10: =SUMIFS(Fac_Total,Fac_Cliente,$A10,Fac_Mes,10,Fac_Anio,2026,Fac_EstadoAFIP,"<>Anulada") | N10: =SUMIFS(Fac_Total,Fac_Cliente,$A10,Fac_Mes,11,Fac_Anio,2026,Fac_EstadoAFIP,"<>Anulada") | O10: =SUMIFS(Fac_Total,Fac_Cliente,$A10,Fac_Mes,12,Fac_Anio,2026,Fac_EstadoAFIP,"<>Anulada") | P10: =SUM(D10:O10) | Q10: =COUNTIF(D10:O10,">0")/12
A11: CFC | B11: Servicios prestacionales | C11: multi | D11: =SUMIFS(Fac_Total,Fac_Cliente,$A11,Fac_Mes,1,Fac_Anio,2026,Fac_EstadoAFIP,"<>Anulada") | E11: =SUMIFS(Fac_Total,Fac_Cliente,$A11,Fac_Mes,2,Fac_Anio,2026,Fac_EstadoAFIP,"<>Anulada") | F11: =SUMIFS(Fac_Total,Fac_Cliente,$A11,Fac_Mes,3,Fac_Anio,2026,Fac_EstadoAFIP,"<>Anulada") | G11: =SUMIFS(Fac_Total,Fac_Cliente,$A11,Fac_Mes,4,Fac_Anio,2026,Fac_EstadoAFIP,"<>Anulada") | H11: =SUMIFS(Fac_Total,Fac_Cliente,$A11,Fac_Mes,5,Fac_Anio,2026,Fac_EstadoAFIP,"<>Anulada") | I11: =SUMIFS(Fac_Total,Fac_Cliente,$A11,Fac_Mes,6,Fac_Anio,2026,Fac_EstadoAFIP,"<>Anulada") | J11: =SUMIFS(Fac_Total,Fac_Cliente,$A11,Fac_Mes,7,Fac_Anio,2026,Fac_EstadoAFIP,"<>Anulada") | K11: =SUMIFS(Fac_Total,Fac_Cliente,$A11,Fac_Mes,8,Fac_Anio,2026,Fac_EstadoAFIP,"<>Anulada") | L11: =SUMIFS(Fac_Total,Fac_Cliente,$A11,Fac_Mes,9,Fac_Anio,2026,Fac_EstadoAFIP,"<>Anulada") | M11: =SUMIFS(Fac_Total,Fac_Cliente,$A11,Fac_Mes,10,Fac_Anio,2026,Fac_EstadoAFIP,"<>Anulada") | N11: =SUMIFS(Fac_Total,Fac_Cliente,$A11,Fac_Mes,11,Fac_Anio,2026,Fac_EstadoAFIP,"<>Anulada") | O11: =SUMIFS(Fac_Total,Fac_Cliente,$A11,Fac_Mes,12,Fac_Anio,2026,Fac_EstadoAFIP,"<>Anulada") | P11: =SUM(D11:O11) | Q11: =COUNTIF(D11:O11,">0")/12
A13: TOTAL MENSUAL | D13: =SUM(D3:D11) | E13: =SUM(E3:E11) | F13: =SUM(F3:F11) | G13: =SUM(G3:G11) | H13: =SUM(H3:H11) | I13: =SUM(I3:I11) | J13: =SUM(J3:J11) | K13: =SUM(K3:K11) | ... P13: =SUM(P3:P11)
A15: CLIENTES EVENTUALES (mes a mes)
A16: Suma de facturas a clientes que NO están en la lista de fijos arriba.
A17: EVENTUALES | D17: =SUMIFS(Fac_Total,Fac_Mes,1,Fac_Anio,2026,Fac_EstadoAFIP,"<>Anulada")-D13 | E17: =SUMIFS(Fac_Total,Fac_Mes,2,Fac_Anio,2026,Fac_EstadoAFIP,"<>Anulada")-E13 | F17: =SUMIFS(Fac_Total,Fac_Mes,3,Fac_Anio,2026,Fac_EstadoAFIP,"<>Anulada")-F13 | G17: =SUMIFS(Fac_Total,Fac_Mes,4,Fac_Anio,2026,Fac_EstadoAFIP,"<>Anulada")-G13 | H17: =SUMIFS(Fac_Total,Fac_Mes,5,Fac_Anio,2026,Fac_EstadoAFIP,"<>Anulada")-H13 | I17: =SUMIFS(Fac_Total,Fac_Mes,6,Fac_Anio,2026,Fac_EstadoAFIP,"<>Anulada")-I13 | J17: =SUMIFS(Fac_Total,Fac_Mes,7,Fac_Anio,2026,Fac_EstadoAFIP,"<>Anulada")-J13 | K17: =SUMIFS(Fac_Total,Fac_Mes,8,Fac_Anio,2026,Fac_EstadoAFIP,"<>Anulada")-K13 | L17: =SUMIFS(Fac_Total,Fac_Mes,9,Fac_Anio,2026,Fac_EstadoAFIP,"<>Anulada")-L13 | M17: =SUMIFS(Fac_Total,Fac_Mes,10,Fac_Anio,2026,Fac_EstadoAFIP,"<>Anulada")-M13 | N17: =SUMIFS(Fac_Total,Fac_Mes,11,Fac_Anio,2026,Fac_EstadoAFIP,"<>Anulada")-N13 | O17: =SUMIFS(Fac_Total,Fac_Mes,12,Fac_Anio,2026,Fac_EstadoAFIP,"<>Anulada")-O13 | P17: =SUM(D17:O17)

Sheet Cobranzas
A1: ESTADO DE COBRANZAS
A2: Fecha Factura | B2: Cliente | C2: Concepto | D2: Total Factura | E2: Estado Cobro | F2: Fecha Cobro | G2: Días desde emisión | H2: Período Devengamiento | I2: Observaciones | K2: RESUMEN COBRANZAS
A3: =IF(Facturacion!A2="","",Facturacion!A2) | B3: =IF(Facturacion!E2="","",Facturacion!E2) | C3: =IF(Facturacion!G2="","",Facturacion!G2) | D3: =IF(Facturacion!N2="","",Facturacion!N2) | E3: =IF(Facturacion!S2="","",Facturacion!S2) | F3: =IF(Facturacion!T2="","",Facturacion!T2) | G3: =IF(Facturacion!A2="","",IF(Facturacion!T2<>"",Facturacion!T2-Facturacion!A2,TODAY()-Facturacion!A2)) | H3: =IF(Facturacion!O2="","",Facturacion!O2) | I3: =IF(Facturacion!U2="","",Facturacion!U2) | K3: Total Facturado | L3: =SUM(D3:D502)
A4: =IF(Facturacion!A3="","",Facturacion!A3) | B4: =IF(Facturacion!E3="","",Facturacion!E3) | C4: =IF(Facturacion!G3="","",Facturacion!G3) | D4: =IF(Facturacion!N3="","",Facturacion!N3) | E4: =IF(Facturacion!S3="","",Facturacion!S3) | F4: =IF(Facturacion!T3="","",Facturacion!T3) | G4: =IF(Facturacion!A3="","",IF(Facturacion!T3<>"",Facturacion!T3-Facturacion!A3,TODAY()-Facturacion!A3)) | H4: =IF(Facturacion!O3="","",Facturacion!O3) | I4: =IF(Facturacion!U3="","",Facturacion!U3) | K4: Total Cobrado | L4: =SUMIF(E3:E502,"Cobrada",D3:D502)
A5: =IF(Facturacion!A4="","",Facturacion!A4) | B5: =IF(Facturacion!E4="","",Facturacion!E4) | C5: =IF(Facturacion!G4="","",Facturacion!G4) | D5: =IF(Facturacion!N4="","",Facturacion!N4) | E5: =IF(Facturacion!S4="","",Facturacion!S4) | F5: =IF(Facturacion!T4="","",Facturacion!T4) | G5: =IF(Facturacion!A4="","",IF(Facturacion!T4<>"",Facturacion!T4-Facturacion!A4,TODAY()-Facturacion!A4)) | H5: =IF(Facturacion!O4="","",Facturacion!O4) | I5: =IF(Facturacion!U4="","",Facturacion!U4) | K5: Total Pendiente | L5: =SUMIF(E3:E502,"Pendiente",D3:D502)
A6: =IF(Facturacion!A5="","",Facturacion!A5) | B6: =IF(Facturacion!E5="","",Facturacion!E5) | C6: =IF(Facturacion!G5="","",Facturacion!G5) | D6: =IF(Facturacion!N5="","",Facturacion!N5) | E6: =IF(Facturacion!S5="","",Facturacion!S5) | F6: =IF(Facturacion!T5="","",Facturacion!T5) | G6: =IF(Facturacion!A5="","",IF(Facturacion!T5<>"",Facturacion!T5-Facturacion!A5,TODAY()-Facturacion!A5)) | H6: =IF(Facturacion!O5="","",Facturacion!O5) | I6: =IF(Facturacion!U5="","",Facturacion!U5) | K6: Total Vencido | L6: =SUMIF(E3:E502,"Vencida",D3:D502)
A7: =IF(Facturacion!A6="","",Facturacion!A6) | B7: =IF(Facturacion!E6="","",Facturacion!E6) | C7: =IF(Facturacion!G6="","",Facturacion!G6) | D7: =IF(Facturacion!N6="","",Facturacion!N6) | E7: =IF(Facturacion!S6="","",Facturacion!S6) | F7: =IF(Facturacion!T6="","",Facturacion!T6) | G7: =IF(Facturacion!A6="","",IF(Facturacion!T6<>"",Facturacion!T6-Facturacion!A6,TODAY()-Facturacion!A6)) | H7: =IF(Facturacion!O6="","",Facturacion!O6) | I7: =IF(Facturacion!U6="","",Facturacion!U6) | K7: % Cobrado | L7: =IFERROR(L4/L3,0)
A8: =IF(Facturacion!A7="","",Facturacion!A7) | B8: =IF(Facturacion!E7="","",Facturacion!E7) | C8: =IF(Facturacion!G7="","",Facturacion!G7) | D8: =IF(Facturacion!N7="","",Facturacion!N7) | E8: =IF(Facturacion!S7="","",Facturacion!S7) | F8: =IF(Facturacion!T7="","",Facturacion!T7) | G8: =IF(Facturacion!A7="","",IF(Facturacion!T7<>"",Facturacion!T7-Facturacion!A7,TODAY()-Facturacion!A7)) | H8: =IF(Facturacion!O7="","",Facturacion!O7) | I8: =IF(Facturacion!U7="","",Facturacion!U7)
A9: =IF(Facturacion!A8="","",Facturacion!A8) | B9: =IF(Facturacion!E8="","",Facturacion!E8) | C9: =IF(Facturacion!G8="","",Facturacion!G8) | D9: =IF(Facturacion!N8="","",Facturacion!N8) | E9: =IF(Facturacion!S8="","",Facturacion!S8) | F9: =IF(Facturacion!T8="","",Facturacion!T8) | G9: =IF(Facturacion!A8="","",IF(Facturacion!T8<>"",Facturacion!T8-Facturacion!A8,TODAY()-Facturacion!A8)) | H9: =IF(Facturacion!O8="","",Facturacion!O8) | I9: =IF(Facturacion!U8="","",Facturacion!U8)
A10: =IF(Facturacion!A9="","",Facturacion!A9) | B10: =IF(Facturacion!E9="","",Facturacion!E9) | C10: =IF(Facturacion!G9="","",Facturacion!G9) | D10: =IF(Facturacion!N9="","",Facturacion!N9) | E10: =IF(Facturacion!S9="","",Facturacion!S9) | F10: =IF(Facturacion!T9="","",Facturacion!T9) | G10: =IF(Facturacion!A9="","",IF(Facturacion!T9<>"",Facturacion!T9-Facturacion!A9,TODAY()-Facturacion!A9)) | H10: =IF(Facturacion!O9="","",Facturacion!O9) | I10: =IF(Facturacion!U9="","",Facturacion!U9)
A11: =IF(Facturacion!A10="","",Facturacion!A10) | B11: =IF(Facturacion!E10="","",Facturacion!E10) | C11: =IF(Facturacion!G10="","",Facturacion!G10) | D11: =IF(Facturacion!N10="","",Facturacion!N10) | E11: =IF(Facturacion!S10="","",Facturacion!S10) | F11: =IF(Facturacion!T10="","",Facturacion!T10) | G11: =IF(Facturacion!A10="","",IF(Facturacion!T10<>"",Facturacion!T10-Facturacion!A10,TODAY()-Facturacion!A10)) | H11: =IF(Facturacion!O10="","",Facturacion!O10) | I11: =IF(Facturacion!U10="","",Facturacion!U10)
A12: =IF(Facturacion!A11="","",Facturacion!A11) | B12: =IF(Facturacion!E11="","",Facturacion!E11) | C12: =IF(Facturacion!G11="","",Facturacion!G11) | D12: =IF(Facturacion!N11="","",Facturacion!N11) | E12: =IF(Facturacion!S11="","",Facturacion!S11) | F12: =IF(Facturacion!T11="","",Facturacion!T11) | G12: =IF(Facturacion!A11="","",IF(Facturacion!T11<>"",Facturacion!T11-Facturacion!A11,TODAY()-Facturacion!A11)) | H12: =IF(Facturacion!O11="","",Facturacion!O11) | I12: =IF(Facturacion!U11="","",Facturacion!U11)
A13: =IF(Facturacion!A12="","",Facturacion!A12) | B13: =IF(Facturacion!E12="","",Facturacion!E12) | C13: =IF(Facturacion!G12="","",Facturacion!G12) | D13: =IF(Facturacion!N12="","",Facturacion!N12) | E13: =IF(Facturacion!S12="","",Facturacion!S12) | F13: =IF(Facturacion!T12="","",Facturacion!T12) | G13: =IF(Facturacion!A12="","",IF(Facturacion!T12<>"",Facturacion!T12-Facturacion!A12,TODAY()-Facturacion!A12)) | H13: =IF(Facturacion!O12="","",Facturacion!O12) | I13: =IF(Facturacion!U12="","",Facturacion!U12)
A14: =IF(Facturacion!A13="","",Facturacion!A13) | B14: =IF(Facturacion!E13="","",Facturacion!E13) | C14: =IF(Facturacion!G13="","",Facturacion!G13) | D14: =IF(Facturacion!N13="","",Facturacion!N13) | E14: =IF(Facturacion!S13="","",Facturacion!S13) | F14: =IF(Facturacion!T13="","",Facturacion!T13) | G14: =IF(Facturacion!A13="","",IF(Facturacion!T13<>"",Facturacion!T13-Facturacion!A13,TODAY()-Facturacion!A13)) | H14: =IF(Facturacion!O13="","",Facturacion!O13) | I14: =IF(Facturacion!U13="","",Facturacion!U13)
A15: =IF(Facturacion!A14="","",Facturacion!A14) | B15: =IF(Facturacion!E14="","",Facturacion!E14) | C15: =IF(Facturacion!G14="","",Facturacion!G14) | D15: =IF(Facturacion!N14="","",Facturacion!N14) | E15: =IF(Facturacion!S14="","",Facturacion!S14) | F15: =IF(Facturacion!T14="","",Facturacion!T14) | G15: =IF(Facturacion!A14="","",IF(Facturacion!T14<>"",Facturacion!T14-Facturacion!A14,TODAY()-Facturacion!A14)) | H15: =IF(Facturacion!O14="","",Facturacion!O14) | I15: =IF(Facturacion!U14="","",Facturacion!U14)
A16: =IF(Facturacion!A15="","",Facturacion!A15) | B16: =IF(Facturacion!E15="","",Facturacion!E15) | C16: =IF(Facturacion!G15="","",Facturacion!G15) | D16: =IF(Facturacion!N15="","",Facturacion!N15) | E16: =IF(Facturacion!S15="","",Facturacion!S15) | F16: =IF(Facturacion!T15="","",Facturacion!T15) | G16: =IF(Facturacion!A15="","",IF(Facturacion!T15<>"",Facturacion!T15-Facturacion!A15,TODAY()-Facturacion!A15)) | H16: =IF(Facturacion!O15="","",Facturacion!O15) | I16: =IF(Facturacion!U15="","",Facturacion!U15)
A17: =IF(Facturacion!A16="","",Facturacion!A16) | B17: =IF(Facturacion!E16="","",Facturacion!E16) | C17: =IF(Facturacion!G16="","",Facturacion!G16) | D17: =IF(Facturacion!N16="","",Facturacion!N16) | E17: =IF(Facturacion!S16="","",Facturacion!S16) | F17: =IF(Facturacion!T16="","",Facturacion!T16) | G17: =IF(Facturacion!A16="","",IF(Facturacion!T16<>"",Facturacion!T16-Facturacion!A16,TODAY()-Facturacion!A16)) | H17: =IF(Facturacion!O16="","",Facturacion!O16) | I17: =IF(Facturacion!U16="","",Facturacion!U16)
A18: =IF(Facturacion!A17="","",Facturacion!A17) | B18: =IF(Facturacion!E17="","",Facturacion!E17) | C18: =IF(Facturacion!G17="","",Facturacion!G17) | D18: =IF(Facturacion!N17="","",Facturacion!N17) | E18: =IF(Facturacion!S17="","",Facturacion!S17) | F18: =IF(Facturacion!T17="","",Facturacion!T17) | G18: =IF(Facturacion!A17="","",IF(Facturacion!T17<>"",Facturacion!T17-Facturacion!A17,TODAY()-Facturacion!A17)) | H18: =IF(Facturacion!O17="","",Facturacion!O17) | I18: =IF(Facturacion!U17="","",Facturacion!U17)
A19: =IF(Facturacion!A18="","",Facturacion!A18) | B19: =IF(Facturacion!E18="","",Facturacion!E18) | C19: =IF(Facturacion!G18="","",Facturacion!G18) | D19: =IF(Facturacion!N18="","",Facturacion!N18) | E19: =IF(Facturacion!S18="","",Facturacion!S18) | F19: =IF(Facturacion!T18="","",Facturacion!T18) | G19: =IF(Facturacion!A18="","",IF(Facturacion!T18<>"",Facturacion!T18-Facturacion!A18,TODAY()-Facturacion!A18)) | H19: =IF(Facturacion!O18="","",Facturacion!O18) | I19: =IF(Facturacion!U18="","",Facturacion!U18)
... A502: =IF(Facturacion!A501="","",Facturacion!A501) | B502: =IF(Facturacion!E501="","",Facturacion!E501) | C502: =IF(Facturacion!G501="","",Facturacion!G501) | D502: =IF(Facturacion!N501="","",Facturacion!N501) | E502: =IF(Facturacion!S501="","",Facturacion!S501) | F502: =IF(Facturacion!T501="","",Facturacion!T501) | G502: =IF(Facturacion!A501="","",IF(Facturacion!T501<>"",Facturacion!T501-Facturacion!A501,TODAY()-Facturacion!A501)) | H502: =IF(Facturacion!O501="","",Facturacion!O501) | I502: =IF(Facturacion!U501="","",Facturacion!U501)

Sheet Impuestos
A1: CÁLCULO DE IMPUESTOS APROXIMADO - 2026
A2: Concepto | B2: Ene | C2: Feb | D2: Mar | E2: Abr | F2: May | G2: Jun | H2: Jul | I2: Ago | J2: Sep | K2: Oct | L2: Nov | M2: Dic | N2: Total Año | O2: Notas
A3: BASE: Facturación mensual
