Workbook

Sheet INSTRUCCIONES
B2: PLANILLA MAESTRA DE PRESTADORES
B3: Como usar esta planilla - GRIFF SALUD
B5: QUE ES | C5: Una sola tabla con TODAS las facturas de prestadores. Cada fila es una factura (o una cuota). La columna ESTADO indica en que etapa esta. Los 4 tableros leen de aca.
B7: EL CICLO DE VIDA
B8: 1. PENDIENTE | C8: La factura llego pero todavia no se audito. Se completan los datos de identificacion y el TOTAL.
B9: 2. AUDITADA | C9: Ya pasaron auditoria medica (DEBITO_MEDICO) y facturista (DEBITO_ADMINISTRATIVO). El A_PAGAR quedo firme.
B10: 3. PROYECTADA | C10: Se le asigno una FECHA_PAGO_PROYECTADA. Es un estimativo, se puede mover. Flujo Bancario la cuenta como cheque a emitir.
B11: 4. EMITIDA | C11: Ya se genero el cheque / OP / transferencia. Se cargan NRO_CHEQUE o NRO_OP y FECHA_EMISION_PAGO.
B12: 5. PAGADA | C12: El cheque se deposito o la transferencia se ejecuto. Se carga FECHA_PAGO_REAL.
B14: COMO SE COMPLETA
B15: Columnas fondo gris | C15: Son CALCULADAS (A_PAGAR, FECHA_PAGO_SUGERIDA, KPIs). No se tocan: se llenan solas.
B16: Columnas con lista | C16: TIPO_COMPROBANTE, TIPO_PRESTACION, OBRA_SOCIAL, ESTADO, ETAPA_AUDITORIA, METODO_PAGO y ESTADO_CHEQUE_BANCO tienen lista desplegable.
B17: Filas amarillas | C17: Son 2 filas de EJEMPLO. Borralas antes de cargar datos reales.
B18: Celda K1 (amarilla) | C18: Escribir el periodo de la planilla, formato MM-AAAA (ej. 03-2026).
B20: BLOQUES DE COLUMNAS
B21: IDENTIFICACION (azul) | C21: PRESTADOR, CUIT, TIPO_COMPROBANTE (FAC/NC/ND), NUMERO_COMPROBANTE, FECHA, PERIODO, TIPO_PRESTACION, OBRA_SOCIAL, PLAZO.
B22: MONTOS (verde) | C22: TOTAL_COMPROBANTE lo carga quien arma la planilla. DEBITO_MEDICO lo carga la medica auditora. DEBITO_ADMINISTRATIVO lo carga la facturista. A_PAGAR se calcula solo.
B23: CICLO (violeta) | C23: ESTADO, ETAPA_AUDITORIA y METODO_PAGO.
B24: HITOS (ambar) | C24: Las 4 fechas del circuito de auditoria. Cada persona anota la fecha cuando recibe / entrega la factura. De aca salen los KPIs.
B25: PROYECCION (lila) | C25: FECHA_PAGO_SUGERIDA = FECHA + PLAZO (calculada). FECHA_PAGO_PROYECTADA es editable. MONTO_PROYECTADO: el monto de esa cuota.
B26: EMISION (azul claro) | C26: NRO_OP, NRO_CHEQUE, FECHA_EMISION_PAGO, BANCO_EMISOR. Varias se autocompletan al cruzar con Galicia / Colppy.
B27: PAGO (gris) | C27: FECHA_PAGO_REAL y ESTADO_CHEQUE_BANCO (lo que dice Galicia).
B28: KPI (naranja) | C28: 6 indicadores de tiempo, todos calculados. Miden cuantos dias tarda cada etapa del proceso.
B29: SEGUIMIENTO (gris) | C29: USUARIO_MODIFICO, FECHA_ULTIMA_MODIFICACION y NOTAS.
B31: CUOTAS MULTIPLES | C31: Si una factura se paga en varias cuotas: una fila por cuota. Todas con el mismo NUMERO_COMPROBANTE, distinto MONTO_PROYECTADO y FECHA_PAGO_PROYECTADA. La columna NRO_CUOTA muestra 1 de 2, 2 de 2, etc.
B33: KPIs DEL PROCESO
B34: KPI_DEMORA_A_AUDITORIA | C34: Dias desde que llego la doc hasta que entro a auditoria medica.
B35: KPI_DIAS_AUD_MEDICA | C35: Dias que la factura estuvo en la medica auditora.
B36: KPI_DIAS_FACTURISTA | C36: Dias que la factura estuvo en la facturista.
B37: KPI_LEADTIME_AUDITORIA | C37: Dias totales de auditoria: recepcion hasta fin auditoria.
B38: KPI_DEMORA_AUD_A_PAGO | C38: Dias entre fin de auditoria y emision del pago.
B39: KPI_LEADTIME_TOTAL | C39: Dias totales: recepcion hasta pago real.

Sheet PANEL
B2: PANEL DE CONTROL
B3: Se actualiza solo a partir de la hoja PRESTADORES
B5: FACTURAS POR ESTADO | F5: MONTO A_PAGAR POR OBRA SOCIAL
B6: ESTADO | C6: CANTIDAD | D6: MONTO A_PAGAR | F6: OBRA SOCIAL | G6: CANTIDAD | H6: MONTO A_PAGAR
B7: PENDIENTE | C7: =COUNTIF(PRESTADORES!$O$4:$O$503,"PENDIENTE") -> 0 | D7: =SUMIF(PRESTADORES!$O$4:$O$503,"PENDIENTE",PRESTADORES!$N$4:$N$503) -> 0 | F7: OSPEVIC | G7: =COUNTIF(PRESTADORES!$I$4:$I$503,"OSPEVIC") -> 92 | H7: =SUMIF(PRESTADORES!$I$4:$I$503,"OSPEVIC",PRESTADORES!$N$4:$N$503) -> 1.945367e+08
B8: AUDITADA | C8: =COUNTIF(PRESTADORES!$O$4:$O$503,"AUDITADA") -> 211 | D8: =SUMIF(PRESTADORES!$O$4:$O$503,"AUDITADA",PRESTADORES!$N$4:$N$503) -> 2.7250785e+08 | F8: OSPIF | G8: =COUNTIF(PRESTADORES!$I$4:$I$503,"OSPIF") -> 64 | H8: =SUMIF(PRESTADORES!$I$4:$I$503,"OSPIF",PRESTADORES!$N$4:$N$503) -> 53726268
B9: PROYECTADA | C9: =COUNTIF(PRESTADORES!$O$4:$O$503,"PROYECTADA") -> 0 | D9: =SUMIF(PRESTADORES!$O$4:$O$503,"PROYECTADA",PRESTADORES!$N$4:$N$503) -> 0 | F9: OSPLYFC | G9: =COUNTIF(PRESTADORES!$I$4:$I$503,"OSPLYFC") -> 36 | H9: =SUMIF(PRESTADORES!$I$4:$I$503,"OSPLYFC",PRESTADORES!$N$4:$N$503) -> 13977107
B10: EMITIDA | C10: =COUNTIF(PRESTADORES!$O$4:$O$503,"EMITIDA") -> 0 | D10: =SUMIF(PRESTADORES!$O$4:$O$503,"EMITIDA",PRESTADORES!$N$4:$N$503) -> 0 | F10: OSPM | G10: =COUNTIF(PRESTADORES!$I$4:$I$503,"OSPM") -> 4 | H10: =SUMIF(PRESTADORES!$I$4:$I$503,"OSPM",PRESTADORES!$N$4:$N$503) -> 1729983.5
B11: PAGADA | C11: =COUNTIF(PRESTADORES!$O$4:$O$503,"PAGADA") -> 0 | D11: =SUMIF(PRESTADORES!$O$4:$O$503,"PAGADA",PRESTADORES!$N$4:$N$503) -> 0 | F11: OSSURRBAC | G11: =COUNTIF(PRESTADORES!$I$4:$I$503,"OSSURRBAC") -> 15 | H11: =SUMIF(PRESTADORES!$I$4:$I$503,"OSSURRBAC",PRESTADORES!$N$4:$N$503) -> 8537787.1
B12: TOTAL | C12: =SUM(C7:C11) -> 211 | D12: =SUM(D7:D11) -> 2.7250785e+08 | F12: AMSURRBAC | G12: =COUNTIF(PRESTADORES!$I$4:$I$503,"AMSURRBAC") -> 0 | H12: =SUMIF(PRESTADORES!$I$4:$I$503,"AMSURRBAC",PRESTADORES!$N$4:$N$503) -> 0
F13: UOM | G13: =COUNTIF(PRESTADORES!$I$4:$I$503,"UOM") -> 0 | H13: =SUMIF(PRESTADORES!$I$4:$I$503,"UOM",PRESTADORES!$N$4:$N$503) -> 0
B14: FACTURAS EN AUDITORIA (sub-etapa) | F14: SIN ASIGNACION | G14: =COUNTIF(PRESTADORES!$I$4:$I$503,"SIN ASIGNACION") -> 0 | H14: =SUMIF(PRESTADORES!$I$4:$I$503,"SIN ASIGNACION",PRESTADORES!$N$4:$N$503) -> 0
B15: ETAPA_AUDITORIA | C15: CANTIDAD | F15: TOTAL | G15: =SUM(G7:G14) -> 211 | H15: =SUM(H7:H14) -> 2.7250785e+08
B16: RECIBIDA | C16: =COUNTIF(PRESTADORES!$P$4:$P$503,"RECIBIDA") -> 0
B17: EN_AUD_MEDICA | C17: =COUNTIF(PRESTADORES!$P$4:$P$503,"EN_AUD_MEDICA") -> 0
B18: EN_FACTURISTA | C18: =COUNTIF(PRESTADORES!$P$4:$P$503,"EN_FACTURISTA") -> 0
B19: AUDITADA | C19: =COUNTIF(PRESTADORES!$P$4:$P$503,"AUDITADA") -> 211
B21: KPIs PROMEDIO (dias)
B22: INDICADOR | C22: PROMEDIO DIAS
B23: Demora a auditoria | C23: =IFERROR(AVERAGE(PRESTADORES!$AF$4:$AF$503),"-") -> -
B24: Dias en aud. medica | C24: =IFERROR(AVERAGE(PRESTADORES!$AG$4:$AG$503),"-") -> -
B25: Dias en facturista | C25: =IFERROR(AVERAGE(PRESTADORES!$AH$4:$AH$503),"-") -> -
B26: Lead time auditoria | C26: =IFERROR(AVERAGE(PRESTADORES!$AI$4:$AI$503),"-") -> -
B27: Demora aud. a pago | C27: =IFERROR(AVERAGE(PRESTADORES!$AJ$4:$AJ$503),"-") -> -
B28: Lead time total | C28: =IFERROR(AVERAGE(PRESTADORES!$AK$4:$AK$503),"-") -> -

Sheet PRESTADORES
A1: PLANILLA MAESTRA DE PRESTADORES - GRIFF SALUD | J1: Periodo: | K1: 02-2026
A3: ID | B3: PRESTADOR | C3: CUIT | D3: TIPO_COMPROBANTE | E3: NUMERO_COMPROBANTE | F3: FECHA_COMPROBANTE | G3: PERIODO_PRESTACION | H3: TIPO_PRESTACION | I3: OBRA_SOCIAL | J3: PLAZO | K3: TOTAL_COMPROBANTE | L3: DEBITO_ADMINISTRATIVO | M3: DEBITO_MEDICO | N3: A_PAGAR | O3: ESTADO | P3: ETAPA_AUDITORIA | Q3: METODO_PAGO | R3: FECHA_RECEPCION | S3: FECHA_A_AUD_MEDICA | T3: FECHA_A_FACTURISTA | U3: FECHA_FIN_AUDITORIA | V3: NRO_CUOTA | W3: FECHA_PAGO_SUGERIDA | X3: FECHA_PAGO_PROYECTADA | Y3: MONTO_PROYECTADO | Z3: NRO_OP | AA3: NRO_CHEQUE | AB3: FECHA_EMISION_PAGO | AC3: BANCO_EMISOR | AD3: FECHA_PAGO_REAL | AE3: ESTADO_CHEQUE_BANCO | AF3: KPI_DEMORA_A_AUDITORIA | AG3: KPI_DIAS_AUD_MEDICA | AH3: KPI_DIAS_FACTURISTA | AI3: KPI_LEADTIME_AUDITORIA | AJ3: KPI_DEMORA_AUD_A_PAGO | AK3: KPI_LEADTIME_TOTAL | AL3: USUARIO_MODIFICO | AM3: FECHA_ULTIMA_MODIFICACION | AN3: NOTAS
A4: =IF($B4="","",ROW()-3) -> 1 | B4: AMPARAR S.R.L | C4: 30708686499 | D4: FAC | E4: 00008-00001805 | F4: 46083 | H4: CAPITAS | I4: OSSURRBAC | J4: 30 | K4: 314997.76 | L4: 0 | M4: 0 | N4: =IF($K4="","",$K4-N($L4)-N($M4)) -> 314997.76 | O4: AUDITADA | P4: AUDITADA | V4: 1 de 1 | W4: =IF(OR($F4="",$J4=""),"",$F4+$J4) -> 46113 | AF4: =IF(OR($R4="",$S4=""),"",$S4-$R4) | AG4: =IF(OR($S4="",$T4=""),"",$T4-$S4) | AH4: =IF(OR($T4="",$U4=""),"",$U4-$T4) | AI4: =IF(OR($R4="",$U4=""),"",$U4-$R4) | AJ4: =IF(OR($U4="",$AB4=""),"",$AB4-$U4) | AK4: =IF(OR($R4="",$AD4=""),"",$AD4-$R4) | AN4: Migrado (02-2026)
A5: =IF($B5="","",ROW()-3) -> 2 | B5: AMPARAR S.R.L | C5: 30708686499 | D5: FAC | E5: 00008-00001803 | F5: 46083 | H5: CAPITAS | I5: OSPLYFC | J5: 30 | K5: 726056.45 | L5: 0 | M5: 0 | N5: =IF($K5="","",$K5-N($L5)-N($M5)) -> 726056.45 | O5: AUDITADA | P5: AUDITADA | V5: 1 de 1 | W5: =IF(OR($F5="",$J5=""),"",$F5+$J5) -> 46113 | AF5: =IF(OR($R5="",$S5=""),"",$S5-$R5) | AG5: =IF(OR($S5="",$T5=""),"",$T5-$S5) | AH5: =IF(OR($T5="",$U5=""),"",$U5-$T5) | AI5: =IF(OR($R5="",$U5=""),"",$U5-$R5) | AJ5: =IF(OR($U5="",$AB5=""),"",$AB5-$U5) | AK5: =IF(OR($R5="",$AD5=""),"",$AD5-$R5) | AN5: Migrado (02-2026)
A6: =IF($B6="","",ROW()-3) -> 3 | B6: AMPARAR S.R.L | C6: 30708686499 | D6: FAC | E6: 00008-00001806 | F6: 46083 | H6: CAPITAS | I6: OSPIF | J6: 30 | K6: 2955934.5 | L6: 0 | M6: 0 | N6: =IF($K6="","",$K6-N($L6)-N($M6)) -> 2955934.5 | O6: AUDITADA | P6: AUDITADA | V6: 1 de 1 | W6: =IF(OR($F6="",$J6=""),"",$F6+$J6) -> 46113 | AF6: =IF(OR($R6="",$S6=""),"",$S6-$R6) | AG6: =IF(OR($S6="",$T6=""),"",$T6-$S6) | AH6: =IF(OR($T6="",$U6=""),"",$U6-$T6) | AI6: =IF(OR($R6="",$U6=""),"",$U6-$R6) | AJ6: =IF(OR($U6="",$AB6=""),"",$AB6-$U6) | AK6: =IF(OR($R6="",$AD6=""),"",$AD6-$R6) | AN6: Migrado (02-2026)
A7: =IF($B7="","",ROW()-3) -> 4 | B7: AMPARAR S.R.L | C7: 30708686499 | D7: FAC | E7: 00008-00001807 | F7: 46083 | H7: AMBULATORIO | I7: OSPEVIC | J7: 30 | K7: 14374.8 | L7: 0 | M7: 0 | N7: =IF($K7="","",$K7-N($L7)-N($M7)) -> 14374.8 | O7: AUDITADA | P7: AUDITADA | V7: 1 de 1 | W7: =IF(OR($F7="",$J7=""),"",$F7+$J7) -> 46113 | AF7: =IF(OR($R7="",$S7=""),"",$S7-$R7) | AG7: =IF(OR($S7="",$T7=""),"",$T7-$S7) | AH7: =IF(OR($T7="",$U7=""),"",$U7-$T7) | AI7: =IF(OR($R7="",$U7=""),"",$U7-$R7) | AJ7: =IF(OR($U7="",$AB7=""),"",$AB7-$U7) | AK7: =IF(OR($R7="",$AD7=""),"",$AD7-$R7) | AN7: Migrado (02-2026)
A8: =IF($B8="","",ROW()-3) -> 5 | B8: AMPARAR S.R.L | C8: 30708686499 | D8: FAC | E8: 00008-00001466 | F8: 46143 | H8: AMBULATORIO | I8: OSPEVIC | J8: 30 | K8: 14374.8 | L8: 2494.8 | M8: 0 | N8: =IF($K8="","",$K8-N($L8)-N($M8)) -> 11880 | O8: AUDITADA | P8: AUDITADA | V8: 1 de 1 | W8: =IF(OR($F8="",$J8=""),"",$F8+$J8) -> 46173 | AF8: =IF(OR($R8="",$S8=""),"",$S8-$R8) | AG8: =IF(OR($S8="",$T8=""),"",$T8-$S8) | AH8: =IF(OR($T8="",$U8=""),"",$U8-$T8) | AI8: =IF(OR($R8="",$U8=""),"",$U8-$R8) | AJ8: =IF(OR($U8="",$AB8=""),"",$AB8-$U8) | AK8: =IF(OR($R8="",$AD8=""),"",$AD8-$R8) | AN8: Migrado (02-2026)
A9: =IF($B9="","",ROW()-3) -> 6 | B9: AMPARAR S.R.L | C9: 30708686499 | D9: FAC | E9: 00008-00001824 | F9: 46083 | H9: TRASLADOS | I9: OSPEVIC | J9: 30 | K9: 1034649.6 | L9: 98600.81 | M9: 0 | N9: =IF($K9="","",$K9-N($L9)-N($M9)) -> 936048.76 | O9: AUDITADA | P9: AUDITADA | V9: 1 de 1 | W9: =IF(OR($F9="",$J9=""),"",$F9+$J9) -> 46113 | AF9: =IF(OR($R9="",$S9=""),"",$S9-$R9) | AG9: =IF(OR($S9="",$T9=""),"",$T9-$S9) | AH9: =IF(OR($T9="",$U9=""),"",$U9-$T9) | AI9: =IF(OR($R9="",$U9=""),"",$U9-$R9) | AJ9: =IF(OR($U9="",$AB9=""),"",$AB9-$U9) | AK9: =IF(OR($R9="",$AD9=""),"",$AD9-$R9) | AN9: Migrado (02-2026)
A10: =IF($B10="","",ROW()-3) -> 7 | B10: AMPARAR S.R.L | C10: 30708686499 | D10: FAC | E10: 00008-00001792 | F10: 46083 | H10: TRASLADOS | I10: OSPEVIC | J10: 30 | K10: 2028447.3 | L10: 562560.09 | M10: 0 | N10: =IF($K10="","",$K10-N($L10)-N($M10)) -> 1465887.2 | O10: AUDITADA | P10: AUDITADA | V10: 1 de 1 | W10: =IF(OR($F10="",$J10=""),"",$F10+$J10) -> 46113 | AF10: =IF(OR($R10="",$S10=""),"",$S10-$R10) | AG10: =IF(OR($S10="",$T10=""),"",$T10-$S10) | AH10: =IF(OR($T10="",$U10=""),"",$U10-$T10) | AI10: =IF(OR($R10="",$U10=""),"",$U10-$R10) | AJ10: =IF(OR($U10="",$AB10=""),"",$AB10-$U10) | AK10: =IF(OR($R10="",$AD10=""),"",$AD10-$R10) | AN10: Migrado (02-2026)
A11: =IF($B11="","",ROW()-3) -> 8 | B11: ASOCIACION DE BIOQUIMICOS DEL DEPARTAMENTO SAN MARTIN | C11: 30582058608 | D11: FAC | E11: 00005-00006083 | F11: 46087 | H11: AMBULATORIO | I11: OSPIF | J11: 30 | K11: 2993255.5 | L11: 2993255.5 | M11: 0 | N11: =IF($K11="","",$K11-N($L11)-N($M11)) -> 0 | O11: AUDITADA | P11: AUDITADA | V11: 1 de 1 | W11: =IF(OR($F11="",$J11=""),"",$F11+$J11) -> 46117 | AF11: =IF(OR($R11="",$S11=""),"",$S11-$R11) | AG11: =IF(OR($S11="",$T11=""),"",$T11-$S11) | AH11: =IF(OR($T11="",$U11=""),"",$U11-$T11) | AI11: =IF(OR($R11="",$U11=""),"",$U11-$R11) | AJ11: =IF(OR($U11="",$AB11=""),"",$AB11-$U11) | AK11: =IF(OR($R11="",$AD11=""),"",$AD11-$R11) | AN11: Migrado (02-2026)
A12: =IF($B12="","",ROW()-3) -> 9 | B12: ASOCIACION DE CLINICAS DEL NORTE DE LA PROVINCIA DE CORDOBA A C L I N O R | C12: 30678724447 | D12: FAC | E12: 00004-00018691 | F12: 46090 | H12: AMBULATORIO | I12: OSPLYFC | J12: 45 | K12: 113487.37 | L12: 8400 | M12: 0 | N12: =IF($K12="","",$K12-N($L12)-N($M12)) -> 105087.37 | O12: AUDITADA | P12: AUDITADA | V12: 1 de 1 | W12: =IF(OR($F12="",$J12=""),"",$F12+$J12) -> 46135 | AF12: =IF(OR($R12="",$S12=""),"",$S12-$R12) | AG12: =IF(OR($S12="",$T12=""),"",$T12-$S12) | AH12: =IF(OR($T12="",$U12=""),"",$U12-$T12) | AI12: =IF(OR($R12="",$U12=""),"",$U12-$R12) | AJ12: =IF(OR($U12="",$AB12=""),"",$AB12-$U12) | AK12: =IF(OR($R12="",$AD12=""),"",$AD12-$R12) | AN12: Migrado (02-2026)
A13: =IF($B13="","",ROW()-3) -> 10 | B13: ASOCIACION DE CLINICAS DEL NORTE DE LA PROVINCIA DE CORDOBA A C L I N O R | C13: 30678724447 | D13: FAC | E13: 00004-00018692 | F13: 46090 | H13: AMBULATORIO | I13: OSPIF | J13: 45 | K13: 1296612.8 | L13: 518860.75 | M13: 0 | N13: =IF($K13="","",$K13-N($L13)-N($M13)) -> 777752.09 | O13: AUDITADA | P13: AUDITADA | V13: 1 de 1 | W13: =IF(OR($F13="",$J13=""),"",$F13+$J13) -> 46135 | AF13: =IF(OR($R13="",$S13=""),"",$S13-$R13) | AG13: =IF(OR($S13="",$T13=""),"",$T13-$S13) | AH13: =IF(OR($T13="",$U13=""),"",$U13-$T13) | AI13: =IF(OR($R13="",$U13=""),"",$U13-$R13) | AJ13: =IF(OR($U13="",$AB13=""),"",$AB13-$U13) | AK13: =IF(OR($R13="",$AD13=""),"",$AD13-$R13) | AN13: Migrado (02-2026)
A14: =IF($B14="","",ROW()-3) -> 11 | B14: ASOCIACION DE CLINICAS DEL NORTE DE LA PROVINCIA DE CORDOBA A C L I N O R | C14: 30678724447 | D14: FAC | E14: 00004-00018694 | F14: 46090 | H14: AMBULATORIO | I14: OSPEVIC | J14: 45 | K14: 4854948.2 | L14: 247299.75 | M14: 0 | N14: =IF($K14="","",$K14-N($L14)-N($M14)) -> 4607648.5 | O14: AUDITADA | P14: AUDITADA | V14: 1 de 1 | W14: =IF(OR($F14="",$J14=""),"",$F14+$J14) -> 46135 | AF14: =IF(OR($R14="",$S14=""),"",$S14-$R14) | AG14: =IF(OR($S14="",$T14=""),"",$T14-$S14) | AH14: =IF(OR($T14="",$U14=""),"",$U14-$T14) | AI14: =IF(OR($R14="",$U14=""),"",$U14-$R14) | AJ14: =IF(OR($U14="",$AB14=""),"",$AB14-$U14) | AK14: =IF(OR($R14="",$AD14=""),"",$AD14-$R14) | AN14: Migrado (02-2026)
A15: =IF($B15="","",ROW()-3) -> 12 | B15: ASOCIACION DE CLINICAS DEL NORTE DE LA PROVINCIA DE CORDOBA A C L I N O R | C15: 30678724447 | D15: FAC | E15: 00004-00018693 | F15: 46090 | H15: AMBULATORIO | I15: OSSURRBAC | J15: 45 | K15: 125892.02 | L15: 5600 | M15: 0 | N15: =IF($K15="","",$K15-N($L15)-N($M15)) -> 120292.02 | O15: AUDITADA | P15: AUDITADA | V15: 1 de 1 | W15: =IF(OR($F15="",$J15=""),"",$F15+$J15) -> 46135 | AF15: =IF(OR($R15="",$S15=""),"",$S15-$R15) | AG15: =IF(OR($S15="",$T15=""),"",$T15-$S15) | AH15: =IF(OR($T15="",$U15=""),"",$U15-$T15) | AI15: =IF(OR($R15="",$U15=""),"",$U15-$R15) | AJ15: =IF(OR($U15="",$AB15=""),"",$AB15-$U15) | AK15: =IF(OR($R15="",$AD15=""),"",$AD15-$R15) | AN15: Migrado (02-2026)
... A49: =IF($B49="","",ROW()-3) -> 46 | B49: CLINICA FUSAVIM PRIVADA SRL | C49: 30708409185 | D49: FAC | E49: 6-4506 | F49: 46086 | H49: AMBULATORIO | I49: OSPEVIC | J49: 60 | K49: 92109.63 | L49: 0 | M49: 0 | N49: =IF($K49="","",$K49-N($L49)-N($M49)) -> 92109.63 | O49: AUDITADA | P49: AUDITADA | V49: 1 de 1 | W49: =IF(OR($F49="",$J49=""),"",$F49+$J49) -> 46146 | AF49: =IF(OR($R49="",$S49=""),"",$S49-$R49) | AG49: =IF(OR($S49="",$T49=""),"",$T49-$S49) | AH49: =IF(OR($T49="",$U49=""),"",$U49-$T49) | AI49: =IF(OR($R49="",$U49=""),"",$U49-$R49) | AJ49: =IF(OR($U49="",$AB49=""),"",$AB49-$U49) | AK49: =IF(OR($R49="",$AD49=""),"",$AD49-$R49) | AN49: Migrado (02-2026)
A50: =IF($B50="","",ROW()-3) -> 47 | B50: CLINICA MEDITERRANEA SALUD S A | C50: 30708069791 | D50: FAC | E50: 00003-00022326 | F50: 46083 | I50: OSPIF | K50: 132240 | L50: 0 | M50: 0 | N50: =IF($K50="","",$K50-N($L50)-N($M50)) -> 132240 | O50: AUDITADA | P50: AUDITADA | V50: 1 de 1 | W50: =IF(OR($F50="",$J50=""),"",$F50+$J50) | AF50: =IF(OR($R50="",$S50=""),"",$S50-$R50) | AG50: =IF(OR($S50="",$T50=""),"",$T50-$S50) | AH50: =IF(OR($T50="",$U50=""),"",$U50-$T50) | AI50: =IF(OR($R50="",$U50=""),"",$U50-$R50) | AJ50: =IF(OR($U50="",$AB50=""),"",$AB50-$U50) | AK50: =IF(OR($R50="",$AD50=""),"",$AD50-$R50) | AN50: Migrado (02-2026)
A51: =IF($B51="","",ROW()-3) -> 48 | B51: CLINICA MEDITERRANEA SALUD S A | C51: 30708069791 | D51: FAC | E51: 00003-00022327 | F51: 46083 | I51: OSPIF | K51: 92102 | L51: 0 | M51: 0 | N51: =IF($K51="","",$K51-N($L51)-N($M51)) -> 92102 | O51: AUDITADA | P51: AUDITADA | V51: 1 de 1 | W51: =IF(OR($F51="",$J51=""),"",$F51+$J51) | AF51: =IF(OR($R51="",$S51=""),"",$S51-$R51) | AG51: =IF(OR($S51="",$T51=""),"",$T51-$S51) | AH51: =IF(OR($T51="",$U51=""),"",$U51-$T51) | AI51: =IF(OR($R51="",$U51=""),"",$U51-$R51) | AJ51: =IF(OR($U51="",$AB51=""),"",$AB51-$U51) | AK51: =IF(OR($R51="",$AD51=""),"",$AD51-$R51) | AN51: Migrado (02-2026)
A52: =IF($B52="","",ROW()-3) -> 49 | B52: CLINICA PRIVADA CARAFFA SRL | C52: 30596272165 | D52: FAC | E52: 00015-00001189 | F52: 46083 | H52: AMBULATORIO | I52: OSPEVIC | J52: 60 | K52: 31748.4 | L52: 0 | M52: 0 | N52: =IF($K52="","",$K52-N($L52)-N($M52)) -> 31748.4 | O52: AUDITADA | P52: AUDITADA | V52: 1 de 1 | W52: =IF(OR($F52="",$J52=""),"",$F52+$J52) -> 46143 | AF52: =IF(OR($R52="",$S52=""),"",$S52-$R52) | AG52: =IF(OR($S52="",$T52=""),"",$T52-$S52) | AH52: =IF(OR($T52="",$U52=""),"",$U52-$T52) | AI52: =IF(OR($R52="",$U52=""),"",$U52-$R52) | AJ52: =IF(OR($U52="",$AB52=""),"",$AB52-$U52) | AK52: =IF(OR($R52="",$AD52=""),"",$AD52-$R52) | AN52: Migrado (02-2026)
A53: =IF($B53="","",ROW()-3) -> 50 | B53: CLINICA PRIVADA CARAFFA SRL | C53: 30596272165 | D53: FAC | E53: 00009-00003851 | F53: 46086 | H53: AMBULATORIO | I53: OSPEVIC | J53: 60 | K53: 317307.52 | L53: 0 | M53: 0 | N53: =IF($K53="","",$K53-N($L53)-N($M53)) -> 317307.52 | O53: AUDITADA | P53: AUDITADA | V53: 1 de 1 | W53: =IF(OR($F53="",$J53=""),"",$F53+$J53) -> 46146 | AF53: =IF(OR($R53="",$S53=""),"",$S53-$R53) | AG53: =IF(OR($S53="",$T53=""),"",$T53-$S53) | AH53: =IF(OR($T53="",$U53=""),"",$U53-$T53) | AI53: =IF(OR($R53="",$U53=""),"",$U53-$R53) | AJ53: =IF(OR($U53="",$AB53=""),"",$AB53-$U53) | AK53: =IF(OR($R53="",$AD53=""),"",$AD53-$R53) | AN53: Migrado (02-2026)
A54: =IF($B54="","",ROW()-3) -> 51 | B54: CLINICA PRIVADA CARAFFA SRL | C54: 30596272165 | D54: FAC | E54: 00009-00003852 | F54: 46086 | H54: AMBULATORIO | I54: OSPIF | J54: 60 | K54: 70037.5 | L54: 0 | M54: 0 | N54: =IF($K54="","",$K54-N($L54)-N($M54)) -> 70037.5 | O54: AUDITADA | P54: AUDITADA | V54: 1 de 1 | W54: =IF(OR($F54="",$J54=""),"",$F54+$J54) -> 46146 | AF54: =IF(OR($R54="",$S54=""),"",$S54-$R54) | AG54: =IF(OR($S54="",$T54=""),"",$T54-$S54) | AH54: =IF(OR($T54="",$U54=""),"",$U54-$T54) | AI54: =IF(OR($R54="",$U54=""),"",$U54-$R54) | AJ54: =IF(OR($U54="",$AB54=""),"",$AB54-$U54) | AK54: =IF(OR($R54="",$AD54=""),"",$AD54-$R54) | AN54: Migrado (02-2026)
A55: =IF($B55="","",ROW()-3) -> 52 | B55: CLINICA PRIVADA CARAFFA SRL | C55: 30596272165 | D55: FAC | E55: 00020-00000009 | F55: 46087 | H55: INTERNADO | I55: OSPEVIC | J55: 60 | K55: 80904.1 | L55: 0 | M55: 0 | N55: =IF($K55="","",$K55-N($L55)-N($M55)) -> 80904.1 | O55: AUDITADA | P55: AUDITADA | V55: 1 de 1 | W55: =IF(OR($F55="",$J55=""),"",$F55+$J55) -> 46147 | AF55: =IF(OR($R55="",$S55=""),"",$S55-$R55) | AG55: =IF(OR($S55="",$T55=""),"",$T55-$S55) | AH55: =IF(OR($T55="",$U55=""),"",$U55-$T55) | AI55: =IF(OR($R55="",$U55=""),"",$U55-$R55) | AJ55: =IF(OR($U55="",$AB55=""),"",$AB55-$U55) | AK55: =IF(OR($R55="",$AD55=""),"",$AD55-$R55) | AN55: Migrado (02-2026)
A56: =IF($B56="","",ROW()-3) -> 53 | B56: CLINICA PRIVADA CARAFFA SRL | C56: 30596272165 | D56: FAC | E56: 00020-00000017 | F56: 46090 | H56: INTERNADO | I56: OSPIF | J56: 60 | K56: 1219587.1 | L56: 0 | M56: 449183.02 | N56: =IF($K56="","",$K56-N($L56)-N($M56)) -> 770404.05 | O56: AUDITADA | P56: AUDITADA | V56: 1 de 1 | W56: =IF(OR($F56="",$J56=""),"",$F56+$J56) -> 46150 | AF56: =IF(OR($R56="",$S56=""),"",$S56-$R56) | AG56: =IF(OR($S56="",$T56=""),"",$T56-$S56) | AH56: =IF(OR($T56="",$U56=""),"",$U56-$T56) | AI56: =IF(OR($R56="",$U56=""),"",$U56-$R56) | AJ56: =IF(OR($U56="",$AB56=""),"",$AB56-$U56) | AK56: =IF(OR($R56="",$AD56=""),"",$AD56-$R56) | AN56: Migrado (02-2026)
A57: =IF($B57="","",ROW()-3) -> 54 | B57: CLINICA PRIVADA COAT S. R. L. | C57: 30682285431 | D57: FAC | E57: 00005-00005100 | F57: 46087 | H57: AMBULATORIO | I57: OSPIF | J57: 60 | K57: 50290 | L57: 0 | M57: 0 | N57: =IF($K57="","",$K57-N($L57)-N($M57)) -> 50290 | O57: AUDITADA | P57: AUDITADA | V57: 1 de 1 | W57: =IF(OR($F57="",$J57=""),"",$F57+$J57) -> 46147 | AF57: =IF(OR($R57="",$S57=""),"",$S57-$R57) | AG57: =IF(OR($S57="",$T57=""),"",$T57-$S57) | AH57: =IF(OR($T57="",$U57=""),"",$U57-$T57) | AI57: =IF(OR($R57="",$U57=""),"",$U57-$R57) | AJ57: =IF(OR($U57="",$AB57=""),"",$AB57-$U57) | AK57: =IF(OR($R57="",$AD57=""),"",$AD57-$R57) | AN57: Migrado (02-2026)
A58: =IF($B58="","",ROW()-3) -> 55 | B58: CLINICA PRIVADA COAT S. R. L. | C58: 30682285431 | D58: FAC | E58: 00005-00005105 | F58: 46087 | H58: AMBULATORIO | I58: OSPIF | J58: 60 | K58: 192600 | L58: 0 | M58: 0 | N58: =IF($K58="","",$K58-N($L58)-N($M58)) -> 192600 | O58: AUDITADA | P58: AUDITADA | V58: 1 de 1 | W58: =IF(OR($F58="",$J58=""),"",$F58+$J58) -> 46147 | AF58: =IF(OR($R58="",$S58=""),"",$S58-$R58) | AG58: =IF(OR($S58="",$T58=""),"",$T58-$S58) | AH58: =IF(OR($T58="",$U58=""),"",$U58-$T58) | AI58: =IF(OR($R58="",$U58=""),"",$U58-$R58) | AJ58: =IF(OR($U58="",$AB58=""),"",$AB58-$U58) | AK58: =IF(OR($R58="",$AD58=""),"",$AD58-$R58) | AN58: Migrado (02-2026)
A59: =IF($B59="","",ROW()-3) -> 56 | B59: CLINICA PRIVADA COAT S. R. L. | C59: 30682285431 | D59: FAC | E59: 00005-00005103 | F59: 46087 | H59: AMBULATORIO | I59: OSPEVIC | J59: 60 | K59: 25000 | L59: 0 | M59: 0 | N59: =IF($K59="","",$K59-N($L59)-N($M59)) -> 25000 | O59: AUDITADA | P59: AUDITADA | V59: 1 de 1 | W59: =IF(OR($F59="",$J59=""),"",$F59+$J59) -> 46147 | AF59: =IF(OR($R59="",$S59=""),"",$S59-$R59) | AG59: =IF(OR($S59="",$T59=""),"",$T59-$S59) | AH59: =IF(OR($T59="",$U59=""),"",$U59-$T59) | AI59: =IF(OR($R59="",$U59=""),"",$U59-$R59) | AJ59: =IF(OR($U59="",$AB59=""),"",$AB59-$U59) | AK59: =IF(OR($R59="",$AD59=""),"",$AD59-$R59) | AN59: Migrado (02-2026)
A60: =IF($B60="","",ROW()-3) -> 57 | B60: CLINICA PRIVADA DE LA CIUDAD SOC RESP LTDA | C60: 30660567840 | D60: FAC | E60: 00010-00003960 | F60: 46085 | I60: OSPEVIC | K60: 12541.71 | L60: 0 | M60: 0 | N60: =IF($K60="","",$K60-N($L60)-N($M60)) -> 12541.71 | O60: AUDITADA | P60: AUDITADA | V60: 1 de 1 | W60: =IF(OR($F60="",$J60=""),"",$F60+$J60) | AF60: =IF(OR($R60="",$S60=""),"",$S60-$R60) | AG60: =IF(OR($S60="",$T60=""),"",$T60-$S60) | AH60: =IF(OR($T60="",$U60=""),"",$U60-$T60) | AI60: =IF(OR($R60="",$U60=""),"",$U60-$R60) | AJ60: =IF(OR($U60="",$AB60=""),"",$AB60-$U60) | AK60: =IF(OR($R60="",$AD60=""),"",$AD60-$R60) | AN60: Migrado (02-2026)
A61: =IF($B61="","",ROW()-3) -> 58 | B61: CLINICA PRIVADA DE LA CIUDAD SOC RESP LTDA | C61: 30660567840 | D61: FAC | E61: 00010-00003961 | F61: 46085 | I61: OSPEVIC | K61: 327908.54 | L61: 0 | M61: 0 | N61: =IF($K61="","",$K61-N($L61)-N($M61)) -> 327908.54 | O61: AUDITADA | P61: AUDITADA | V61: 1 de 1 | W61: =IF(OR($F61="",$J61=""),"",$F61+$J61) | AF61: =IF(OR($R61="",$S61=""),"",$S61-$R61) | AG61: =IF(OR($S61="",$T61=""),"",$T61-$S61) | AH61: =IF(OR($T61="",$U61=""),"",$U61-$T61) | AI61: =IF(OR($R61="",$U61=""),"",$U61-$R61) | AJ61: =IF(OR($U61="",$AB61=""),"",$AB61-$U61) | AK61: =IF(OR($R61="",$AD61=""),"",$AD61-$R61) | AN61: Migrado (02-2026)
A62: =IF($B62="","",ROW()-3) -> 59 | B62: CLINICA PRIVADA DE LA CIUDAD SOC RESP LTDA | C62: 30660567840 | D62: FAC | E62: 00010-00003984 | F62: 46086 | I62: OSPIF | K62: 14161.71 | L62: 0 | M62: 0 | N62: =IF($K62="","",$K62-N($L62)-N($M62)) -> 14161.71 | O62: AUDITADA | P62: AUDITADA | V62: 1 de 1 | W62: =IF(OR($F62="",$J62=""),"",$F62+$J62) | AF62: =IF(OR($R62="",$S62=""),"",$S62-$R62) | AG62: =IF(OR($S62="",$T62=""),"",$T62-$S62) | AH62: =IF(OR($T62="",$U62=""),"",$U62-$T62) | AI62: =IF(OR($R62="",$U62=""),"",$U62-$R62) | AJ62: =IF(OR($U62="",$AB62=""),"",$AB62-$U62) | AK62: =IF(OR($R62="",$AD62=""),"",$AD62-$R62) | AN62: Migrado (02-2026)
A63: =IF($B63="","",ROW()-3) -> 60 | B63: CLINICA PRIVADA DE LA CIUDAD SOC RESP LTDA | C63: 30660567840 | D63: FAC | E63: 00010-00003979 | F63: 46086 | I63: OSPLYFC | K63: 286230.12 | L63: 0 | M63: 0 | N63: =IF($K63="","",$K63-N($L63)-N($M63)) -> 286230.12 | O63: AUDITADA | P63: AUDITADA | V63: 1 de 1 | W63: =IF(OR($F63="",$J63=""),"",$F63+$J63) | AF63: =IF(OR($R63="",$S63=""),"",$S63-$R63) | AG63: =IF(OR($S63="",$T63=""),"",$T63-$S63) | AH63: =IF(OR($T63="",$U63=""),"",$U63-$T63) | AI63: =IF(OR($R63="",$U63=""),"",$U63-$R63) | AJ63: =IF(OR($U63="",$AB63=""),"",$AB63-$U63) | AK63: =IF(OR($R63="",$AD63=""),"",$AD63-$R63) | AN63: Migrado (02-2026)
A64: =IF($B64="","",ROW()-3) -> 61 | B64: CLINICA PRIVADA DEAN FUNES SRL | C64: 30708237791 | D64: FAC | E64: 00004-00000912 | F64: 46081 | H64: AMBULATORIO | I64: OSPEVIC | J64: 60 | K64: 24028 | L64: 0 | M64: 0 | N64: =IF($K64="","",$K64-N($L64)-N($M64)) -> 24028 | O64: AUDITADA | P64: AUDITADA | V64: 1 de 1 | W64: =IF(OR($F64="",$J64=""),"",$F64+$J64) -> 46141 | AF64: =IF(OR($R64="",$S64=""),"",$S64-$R64) | AG64: =IF(OR($S64="",$T64=""),"",$T64-$S64) | AH64: =IF(OR($T64="",$U64=""),"",$U64-$T64) | AI64: =IF(OR($R64="",$U64=""),"",$U64-$R64) | AJ64: =IF(OR($U64="",$AB64=""),"",$AB64-$U64) | AK64: =IF(OR($R64="",$AD64=""),"",$AD64-$R64) | AN64: Migrado (02-2026)
A65: =IF($B65="","",ROW()-3) -> 62 | B65: CLINICA PRIVADA DEAN FUNES SRL | C65: 30708237791 | D65: FAC | E65: 0004-00000845 | F65: 45991 | H65: AMBULATORIO | I65: OSPLYFC | J65: 60 | K65: 86139 | L65: 39863 | M65: 0 | N65: =IF($K65="","",$K65-N($L65)-N($M65)) -> 46276 | O65: AUDITADA | P65: AUDITADA | V65: 1 de 1 | W65: =IF(OR($F65="",$J65=""),"",$F65+$J65) -> 46051 | AF65: =IF(OR($R65="",$S65=""),"",$S65-$R65) | AG65: =IF(OR($S65="",$T65=""),"",$T65-$S65) | AH65: =IF(OR($T65="",$U65=""),"",$U65-$T65) | AI65: =IF(OR($R65="",$U65=""),"",$U65-$R65) | AJ65: =IF(OR($U65="",$AB65=""),"",$AB65-$U65) | AK65: =IF(OR($R65="",$AD65=""),"",$AD65-$R65) | AN65: Migrado (02-2026)
A66: =IF($B66="","",ROW()-3) -> 63 | B66: CLINICA PRIVADA DEL SOL S.A. | C66: 30615571454 | D66: FAC | E66: 00008-00020376 | F66: 46087 | H66: INTERNADO | I66: OSPEVIC | J66: 45 | K66: 2837156.9 | L66: 396948.13 | M66: 116008.04 | N66: =IF($K66="","",$K66-N($L66)-N($M66)) -> 2324200.8 | O66: AUDITADA | P66: AUDITADA | V66: 1 de 1 | W66: =IF(OR($F66="",$J66=""),"",$F66+$J66) -> 46132 | AF66: =IF(OR($R66="",$S66=""),"",$S66-$R66) | AG66: =IF(OR($S66="",$T66=""),"",$T66-$S66) | AH66: =IF(OR($T66="",$U66=""),"",$U66-$T66) | AI66: =IF(OR($R66="",$U66=""),"",$U66-$R66) | AJ66: =IF(OR($U66="",$AB66=""),"",$AB66-$U66) | AK66: =IF(OR($R66="",$AD66=""),"",$AD66-$R66) | AN66: Migrado (02-2026)
A67: =IF($B67="","",ROW()-3) -> 64 | B67: CLINICA PRIVADA DEL SOL S.A. | C67: 30615571454 | D67: FAC | E67: 008-00020469 | F67: 46091 | H67: INTERNADO | I67: OSPEVIC | J67: 45 | K67: 378451.43 | L67: 5919.84 | M67: 0 | N67: =IF($K67="","",$K67-N($L67)-N($M67)) -> 372531.59 | O67: AUDITADA | P67: AUDITADA | V67: 1 de 1 | W67: =IF(OR($F67="",$J67=""),"",$F67+$J67) -> 46136 | AF67: =IF(OR($R67="",$S67=""),"",$S67-$R67) | AG67: =IF(OR($S67="",$T67=""),"",$T67-$S67) | AH67: =IF(OR($T67="",$U67=""),"",$U67-$T67) | AI67: =IF(OR($R67="",$U67=""),"",$U67-$R67) | AJ67: =IF(OR($U67="",$AB67=""),"",$AB67-$U67) | AK67: =IF(OR($R67="",$AD67=""),"",$AD67-$R67) | AN67: Migrado (02-2026)
A68: =IF($B68="","",ROW()-3) -> 65 | B68: CLINICA PRIVADA INTEGRAL DE PSIQUIATRIA SAN NICOLAS SRL S. R. L. | C68: 30608875227 | D68: FAC | E68: 00003-00000246 | F68: 46083 | H68: INTERNADO | I68: OSPIF | J68: 60 | K68: 495000 | L68: 0 | M68: 165000 | N68: =IF($K68="","",$K68-N($L68)-N($M68)) -> 330000 | O68: AUDITADA | P68: AUDITADA | V68: 1 de 1 | W68: =IF(OR($F68="",$J68=""),"",$F68+$J68) -> 46143 | AF68: =IF(OR($R68="",$S68=""),"",$S68-$R68) | AG68: =IF(OR($S68="",$T68=""),"",$T68-$S68) | AH68: =IF(OR($T68="",$U68=""),"",$U68-$T68) | AI68: =IF(OR($R68="",$U68=""),"",$U68-$R68) | AJ68: =IF(OR($U68="",$AB68=""),"",$AB68-$U68) | AK68: =IF(OR($R68="",$AD68=""),"",$AD68-$R68) | AN68: Migrado (02-2026)
A69: =IF($B69="","",ROW()-3) -> 66 | B69: CLINICA PRIVADA INTEGRAL DE PSIQUIATRIA SAN NICOLAS SRL S. R. L. | C69: 30608875227 | D69: FAC | E69: 00003-00000245 | F69: 46083 | H69: INTERNADO | I69: OSPEVIC | J69: 60 | K69: 2464000 | L69: 0 | M69: 0 | N69: =IF($K69="","",$K69-N($L69)-N($M69)) -> 2464000 | O69: AUDITADA | P69: AUDITADA | V69: 1 de 1 | W69: =IF(OR($F69="",$J69=""),"",$F69+$J69) -> 46143 | AF69: =IF(OR($R69="",$S69=""),"",$S69-$R69) | AG69: =IF(OR($S69="",$T69=""),"",$T69-$S69) | AH69: =IF(OR($T69="",$U69=""),"",$U69-$T69) | AI69: =IF(OR($R69="",$U69=""),"",$U69-$R69) | AJ69: =IF(OR($U69="",$AB69=""),"",$AB69-$U69) | AK69: =IF(OR($R69="",$AD69=""),"",$AD69-$R69) | AN69: Migrado (02-2026)
A70: =IF($B70="","",ROW()-3) -> 67 | B70: CLINICA PRIVADA INTEGRAL DE PSIQUIATRIA SAN NICOLAS SRL S. R. L. | C70: 30608875227 | D70: FAC | E70: 00003-00000251 | F70: 46084 | H70: AMBULATORIO | I70: OSPEVIC | J70: 60 | K70: 102030 | L70: 0 | M70: 0 | N70: =IF($K70="","",$K70-N($L70)-N($M70)) -> 102030 | O70: AUDITADA | P70: AUDITADA | V70: 1 de 1 | W70: =IF(OR($F70="",$J70=""),"",$F70+$J70) -> 46144 | AF70: =IF(OR($R70="",$S70=""),"",$S70-$R70) | AG70: =IF(OR($S70="",$T70=""),"",$T70-$S70) | AH70: =IF(OR($T70="",$U70=""),"",$U70-$T70) | AI70: =IF(OR($R70="",$U70=""),"",$U70-$R70) | AJ70: =IF(OR($U70="",$AB70=""),"",$AB70-$U70) | AK70: =IF(OR($R70="",$AD70=""),"",$AD70-$R70) | AN70: Migrado (02-2026)
A71: =IF($B71="","",ROW()-3) -> 68 | B71: CLINICA PRIVADA INTEGRAL DE PSIQUIATRIA SAN NICOLAS SRL S. R. L. | C71: 30608875227 | D71: FAC | E71: 00003-00000252 | F71: 46084 | H71: AMBULATORIO | I71: OSPEVIC | J71: 60 | K71: 27234 | L71: 0 | M71: 0 | N71: =IF($K71="","",$K71-N($L71)-N($M71)) -> 27234 | O71: AUDITADA | P71: AUDITADA | V71: 1 de 1 | W71: =IF(OR($F71="",$J71=""),"",$F71+$J71) -> 46144 | AF71: =IF(OR($R71="",$S71=""),"",$S71-$R71) | AG71: =IF(OR($S71="",$T71=""),"",$T71-$S71) | AH71: =IF(OR($T71="",$U71=""),"",$U71-$T71) | AI71: =IF(OR($R71="",$U71=""),"",$U71-$R71) | AJ71: =IF(OR($U71="",$AB71=""),"",$AB71-$U71) | AK71: =IF(OR($R71="",$AD71=""),"",$AD71-$R71) | AN71: Migrado (02-2026)
A72: =IF($B72="","",ROW()-3) -> 69 | B72: CLINICA PRIVADA INTEGRAL DE PSIQUIATRIA SAN NICOLAS SRL S. R. L. | C72: 30608875227 | D72: FAC | E72: 00003-00000253 | F72: 46084 | I72: OSPEVIC | K72: 619431 | L72: 0 | M72: 0 | N72: =IF($K72="","",$K72-N($L72)-N($M72)) -> 619431 | O72: AUDITADA | P72: AUDITADA | V72: 1 de 1 | W72: =IF(OR($F72="",$J72=""),"",$F72+$J72) | AF72: =IF(OR($R72="",$S72=""),"",$S72-$R72) | AG72: =IF(OR($S72="",$T72=""),"",$T72-$S72) | AH72: =IF(OR($T72="",$U72=""),"",$U72-$T72) | AI72: =IF(OR($R72="",$U72=""),"",$U72-$R72) | AJ72: =IF(OR($U72="",$AB72=""),"",$AB72-$U72) | AK72: =IF(OR($R72="",$AD72=""),"",$AD72-$R72) | AN72: Migrado (02-2026)
A73: =IF($B73="","",ROW()-3) -> 70 | B73: CLINICA PRIVADA INTEGRAL DE PSIQUIATRIA SAN NICOLAS SRL S. R. L. | C73: 30608875227 | D73: FAC | E73: 00003-00000249 | F73: 46084 | I73: OSPLYFC | K73: 120970 | L73: 44300 | M73: 0 | N73: =IF($K73="","",$K73-N($L73)-N($M73)) -> 76670 | O73: AUDITADA | P73: AUDITADA | V73: 1 de 1 | W73: =IF(OR($F73="",$J73=""),"",$F73+$J73) | AF73: =IF(OR($R73="",$S73=""),"",$S73-$R73) | AG73: =IF(OR($S73="",$T73=""),"",$T73-$S73) | AH73: =IF(OR($T73="",$U73=""),"",$U73-$T73) | AI73: =IF(OR($R73="",$U73=""),"",$U73-$R73) | AJ73: =IF(OR($U73="",$AB73=""),"",$AB73-$U73) | AK73: =IF(OR($R73="",$AD73=""),"",$AD73-$R73) | AN73: Migrado (02-2026)
A74: =IF($B74="","",ROW()-3) -> 71 | B74: CLINICA PRIVADA INTEGRAL DE PSIQUIATRIA SAN NICOLAS SRL S. R. L. | C74: 30608875227 | D74: FAC | E74: 00003-00000250 | F74: 46084 | I74: OSSURRBAC | K74: 59800 | L74: 12200 | M74: 0 | N74: =IF($K74="","",$K74-N($L74)-N($M74)) -> 47600 | O74: AUDITADA | P74: AUDITADA | V74: 1 de 1 | W74: =IF(OR($F74="",$J74=""),"",$F74+$J74) | AF74: =IF(OR($R74="",$S74=""),"",$S74-$R74) | AG74: =IF(OR($S74="",$T74=""),"",$T74-$S74) | AH74: =IF(OR($T74="",$U74=""),"",$U74-$T74) | AI74: =IF(OR($R74="",$U74=""),"",$U74-$R74) | AJ74: =IF(OR($U74="",$AB74=""),"",$AB74-$U74) | AK74: =IF(OR($R74="",$AD74=""),"",$AD74-$R74) | AN74: Migrado (02-2026)
...

Sheet CONFIG
A1: TIPO_COMPROBANTE | B1: TIPO_PRESTACION | C1: OBRA_SOCIAL | D1: ESTADO | E1: ETAPA_AUDITORIA | F1: METODO_PAGO | G1: ESTADO_CHEQUE_BANCO | I1: Hoja de configuracion - listas para validaciones. No borrar.
A2: FAC | B2: AMBULATORIO | C2: OSPEVIC | D2: PENDIENTE | E2: RECIBIDA | F2: CHEQUE | G2: Aceptado
A3: NC | B3: INTERNADO | C3: OSPIF | D3: AUDITADA | E3: EN_AUD_MEDICA | F3: TRANSFERENCIA | G3: Deposito en proceso
A4: ND | B4: CAPITAS | C4: OSPLYFC | D4: PROYECTADA | E4: EN_FACTURISTA | F4: OP | G4: Pagado
B5: CAPITADO | C5: OSPM | D5: EMITIDA | E5: AUDITADA | F5: EFECTIVO | G5: Anulado
B6: TRASLADOS | C6: OSSURRBAC | D6: PAGADA | G6: Rechazado
B7: AJUSTE | C7: AMSURRBAC | G7: Repudiado
B8: AREA PROTEGIDA | C8: UOM
B9: INTERESES | C9: SIN ASIGNACION
B10: PROTESIS
B11: REFACTURACION
B12: OTROS
